Workbook

Sheet Barang
A1: Kode Barang | B1: Nama Barang | C1: Kategori | D1: Supplier | E1: Satuan | F1: Harga
A2: SKB001 | B2: Soklin bubuk | C2: Detergen | E2: pcs | F2: 5000
A3: YP500 | B3: Yupi 500 | C3: Makanan | E3: pcs | F3: 500
A4: BPT1 | B4: B. putih 1/4 | C4: Rempah | E4: kg | F4: 8500
A5: TGP002 | B5: Tepung peyek | C5: Bumbu | E5: pcs | F5: 1000
A6: IDM002 | B6: Indomilk | C6: Minuman | D6: Sp | E6: pcs | F6: 1500
A7: CLB001 | B7: Chocolatos bubuk | C7: Minuman | E7: pcs | F7: 2500
A8: CL5001 | B8: Chocolatos 500 | C8: Makanan | E8: pcs | F8: 500
A9: LML002 | B9: Le mineral | C9: Minuman | E9: btl | F9: 19000
A10: GL1001 | B10: Gula 1kg | C10: Sembako | E10: kg | F10: 16500
A11: GRM01 | B11: Garam | C11: Bumbu | E11: pcs | F11: 2500
A12: PLS002 | B12: Pilus | C12: Makanan | E12: pcs | F12: 1000
A13: GSL002 | B13: Garuda slondok | C13: Makanan | E13: pcs | F13: 2000
A14: TSP001 | B14: Tisu Peony | C14: Tissue | E14: pcs | F14: 7000
A15: GSB002 | B15: Gery salut besar | C15: Makanan | E15: pcs | F15: 6500
A16: SCB002 | B16: Scoth brite | C16: Spon | E16: pcs | F16: 3500
A17: MBK002 | B17: Mie baked | C17: Makanan | E17: pcs | F17: 3000
A18: RTP001 | B18: Roti Pia | C18: Makanan | E18: pcs | F18: 2000
A19: RYC001 | B19: Royco | C19: Bumbu | D19: Sp | E19: pcs | F19: 500
A20: THD001 | B20: Teh Dandang | C20: Minuman | E20: pcs | F20: 2000
A21: RSB001 | B21: Rinso Bubuk | C21: Detergen | E21: pcs | F21: 5000
A22: PT1/4 | B22: Plastik 1/4 | C22: Plastik | E22: kg | F22: 2000
A23: PT1/2 | B23: Plastik 1/2 | C23: Plastik | E23: kg | F23: 3500
A24: PT1001 | B24: Plastik 1kg | C24: Plastik | E24: kg | F24: 5000
A25: KSK001 | B25: Kresek | C25: Plastik | E25: pack | F25: 4000
A26: GRA001 | B26: Garuda Atom | C26: Makanan | E26: pcs | F26: 2000
A27: DLN001 | B27: Dilan 1000 | C27: Makanan | E27: pcs | F27: 1000
A28: YP1001 | B28: Yupi 1000 | C28: Makanan | E28: pcs | F28: 1000
A29: LFB001 | B29: Lifebouy | C29: Sabun | E29: pcs | F29: 6000
A30: MGR001 | B30: Mie goreng | C30: Makanan | E30: pcs | F30: 3500
A31: MKH001 | B31: Mie kuah | C31: Makanan | E31: pcs | F31: 3500
... A97: TL002 | B97: Telur 2. 1/2 | C97: Sembako | E97: kg | F97: 14500
B98: Telur 2. 1/4 | C98: Sembako | E98: kg | F98: 29000
A99: PT1/4.T | B99: Plastik 1/4 tebal | C99: Plastik | E99: kg | F99: 10000
A100: BBG001 | B100: Bubble gum | C100: Makanan | E100: pcs | F100: 1000
A101: SG2001 | B101: Sari gandum 2 | C101: Makanan | E101: pcs | F101: 2000
A102: SG7001 | B102: Sari gandum 7 | C102: Makanan | E102: pcs | F102: 7500
A103: MRS001 | B103: Mie Ricies | C103: Makanan | E103: pcs | F103: 2500
A104: RDR001 | B104: Roma Durian | C104: Makanan | E104: pcs | F104: 9000
A105: CHR001 | B105: Charm softex | C105: Pembalut | E105: pcs | F105: 7500
...

Sheet 2024
A1: Tanggal | B1: Kode Barang | C1: Nama Barang | D1: Kategori | E1: Satuan | F1: Jual | G1: Harga Jual | H1: Stok Awal | I1: Total | J1: Column 1 | L1: Tanggal | M1: Kode Barang | N1: Nama Barang | O1: Kategori | P1: Satuan | Q1: Kulak | R1: Harga Jual | S1: Harga Kulak | T1: Stok Akhir | U1: Minimal Stok | V1: Supplier
A2: 45292 | B2: {=IF(C2="","", IFERROR(INDEX(Barang!$A$2:$A$10001, MATCH(C2, Barang!$B$2:$B$10001, 0)), "Tidak ditemukan"))} -> KPH001 | C2: KOPI HITAM | D2: {=IF(C2="","", IFERROR(INDEX(Barang!$C$2:$C$10001, MATCH(C2, Barang!$B$2:$B$10001, 0)), ""))} -> Minuman | E2: {=IF(C2="","", IFERROR(INDEX(Barang!$E$2:$E$10001, MATCH(C2, Barang!$B$2:$B$10001, 0)), ""))} -> pcs | F2: 83 | G2: {=IF(C2="","", IFERROR(INDEX(Barang!$F$2:$F$10001, MATCH(C2, Barang!$B$2:$B$10001, 0)) * F2, ""))} -> 83000 | L2: 45292 | M2: BCB001 | N2: Boncabe | O2: Bumbu | P2: bungkus | Q2: 12 | S2: 20000 | T2: 10 | U2: - | V2: -
B3: {=IF(C3="","", IFERROR(INDEX(Barang!$A$2:$A$10001, MATCH(C3, Barang!$B$2:$B$10001, 0)), "Tidak ditemukan"))} -> MSK001 | C3: Masako | D3: {=IF(C3="","", IFERROR(INDEX(Barang!$C$2:$C$10001, MATCH(C3, Barang!$B$2:$B$10001, 0)), ""))} -> Bumbu | E3: {=IF(C3="","", IFERROR(INDEX(Barang!$E$2:$E$10001, MATCH(C3, Barang!$B$2:$B$10001, 0)), ""))} -> pcs | F3: 35 | G3: {=IF(C3="","", IFERROR(INDEX(Barang!$F$2:$F$10001, MATCH(C3, Barang!$B$2:$B$10001, 0)) * F3, ""))} -> 17500 | M3: MSK001 | N3: Masako | O3: Bumbu | P3: bungkus | Q3: 36 | S3: 14000 | T3: 58 | U3: - | V3: -
B4: {=IF(C4="","", IFERROR(INDEX(Barang!$A$2:$A$10001, MATCH(C4, Barang!$B$2:$B$10001, 0)), "Tidak ditemukan"))} -> RTP001 | C4: roti pia | D4: {=IF(C4="","", IFERROR(INDEX(Barang!$C$2:$C$10001, MATCH(C4, Barang!$B$2:$B$10001, 0)), ""))} -> Makanan | E4: {=IF(C4="","", IFERROR(INDEX(Barang!$E$2:$E$10001, MATCH(C4, Barang!$B$2:$B$10001, 0)), ""))} -> pcs | F4: 20 | G4: {=IF(C4="","", IFERROR(INDEX(Barang!$F$2:$F$10001, MATCH(C4, Barang!$B$2:$B$10001, 0)) * F4, ""))} -> 40000 | M4: IDM001 | N4: Indomilk | O4: Minuman | P4: bungkus | Q4: 70 | S4: 77000 | T4: 59 | U4: - | V4: -
B5: {=IF(C5="","", IFERROR(INDEX(Barang!$A$2:$A$10001, MATCH(C5, Barang!$B$2:$B$10001, 0)), "Tidak ditemukan"))} -> NTS001 | C5: Nutrisari | D5: {=IF(C5="","", IFERROR(INDEX(Barang!$C$2:$C$10001, MATCH(C5, Barang!$B$2:$B$10001, 0)), ""))} -> Minuman | E5: {=IF(C5="","", IFERROR(INDEX(Barang!$E$2:$E$10001, MATCH(C5, Barang!$B$2:$B$10001, 0)), ""))} -> pcs | F5: 40 | G5: {=IF(C5="","", IFERROR(INDEX(Barang!$F$2:$F$10001, MATCH(C5, Barang!$B$2:$B$10001, 0)) * F5, ""))} -> 60000 | M5: NTS001 | N5: Nutrisari | O5: Minuman | P5: bungkus | Q5: 60 | S5: 75000 | T5: 57 | U5: - | V5: -
B6: {=IF(C6="","", IFERROR(INDEX(Barang!$A$2:$A$10001, MATCH(C6, Barang!$B$2:$B$10001, 0)), "Tidak ditemukan"))} -> DNY001 | C6: Downy | D6: {=IF(C6="","", IFERROR(INDEX(Barang!$C$2:$C$10001, MATCH(C6, Barang!$B$2:$B$10001, 0)), ""))} -> Detergen | E6: {=IF(C6="","", IFERROR(INDEX(Barang!$E$2:$E$10001, MATCH(C6, Barang!$B$2:$B$10001, 0)), ""))} -> pcs | F6: 60 | G6: {=IF(C6="","", IFERROR(INDEX(Barang!$F$2:$F$10001, MATCH(C6, Barang!$B$2:$B$10001, 0)) * F6, ""))} -> 30000 | M6: DN001 | N6: Downy | O6: Detergen | P6: bungkus | Q6: 36 | S6: 15000 | T6: 82 | U6: - | V6: -
B7: {=IF(C7="","", IFERROR(INDEX(Barang!$A$2:$A$10001, MATCH(C7, Barang!$B$2:$B$10001, 0)), "Tidak ditemukan"))} -> CL5001 | C7: Chocolatos 500 | D7: {=IF(C7="","", IFERROR(INDEX(Barang!$C$2:$C$10001, MATCH(C7, Barang!$B$2:$B$10001, 0)), ""))} -> Makanan | E7: {=IF(C7="","", IFERROR(INDEX(Barang!$E$2:$E$10001, MATCH(C7, Barang!$B$2:$B$10001, 0)), ""))} -> pcs | F7: 72 | G7: {=IF(C7="","", IFERROR(INDEX(Barang!$F$2:$F$10001, MATCH(C7, Barang!$B$2:$B$10001, 0)) * F7, ""))} -> 36000 | M7: CCS001 | N7: Chocolatos | O7: Makanan | P7: bungkus | Q7: 192 | S7: 304000 | T7: 190 | U7: - | V7: -
B8: {=IF(C8="","", IFERROR(INDEX(Barang!$A$2:$A$10001, MATCH(C8, Barang!$B$2:$B$10001, 0)), "Tidak ditemukan"))} -> MCN001 | C8: Micin 1000 | D8: {=IF(C8="","", IFERROR(INDEX(Barang!$C$2:$C$10001, MATCH(C8, Barang!$B$2:$B$10001, 0)), ""))} -> Bumbu | E8: {=IF(C8="","", IFERROR(INDEX(Barang!$E$2:$E$10001, MATCH(C8, Barang!$B$2:$B$10001, 0)), ""))} -> pcs | F8: 23 | G8: {=IF(C8="","", IFERROR(INDEX(Barang!$F$2:$F$10001, MATCH(C8, Barang!$B$2:$B$10001, 0)) * F8, ""))} -> 23000 | M8: MCN001 | N8: Micin | O8: Bumbu | P8: bungkus | Q8: 20 | S8: 18500 | T8: 19 | U8: - | V8: -
B9: {=IF(C9="","", IFERROR(INDEX(Barang!$A$2:$A$10001, MATCH(C9, Barang!$B$2:$B$10001, 0)), "Tidak ditemukan"))} -> BRS1 | C9: Beras 1kg | D9: {=IF(C9="","", IFERROR(INDEX(Barang!$C$2:$C$10001, MATCH(C9, Barang!$B$2:$B$10001, 0)), ""))} -> Sembako | E9: {=IF(C9="","", IFERROR(INDEX(Barang!$E$2:$E$10001, MATCH(C9, Barang!$B$2:$B$10001, 0)), ""))} -> kg | F9: 7 | G9: {=IF(C9="","", IFERROR(INDEX(Barang!$F$2:$F$10001, MATCH(C9, Barang!$B$2:$B$10001, 0)) * F9, ""))} -> 101500 | M9: GDY001 | N9: GoodDay | O9: Minuman | P9: bungkus | Q9: 40 | S9: 72000 | T9: 39 | U9: - | V9: -
B10: {=IF(C10="","", IFERROR(INDEX(Barang!$A$2:$A$10001, MATCH(C10, Barang!$B$2:$B$10001, 0)), "Tidak ditemukan"))} -> TLR2 | C10: Telur 1/2 | D10: {=IF(C10="","", IFERROR(INDEX(Barang!$C$2:$C$10001, MATCH(C10, Barang!$B$2:$B$10001, 0)), ""))} -> Sembako | E10: {=IF(C10="","", IFERROR(INDEX(Barang!$E$2:$E$10001, MATCH(C10, Barang!$B$2:$B$10001, 0)), ""))} -> kg | F10: 12 | G10: {=IF(C10="","", IFERROR(INDEX(Barang!$F$2:$F$10001, MATCH(C10, Barang!$B$2:$B$10001, 0)) * F10, ""))} -> 186000 | I10: =SUM(G2:G10) -> 577000 | M10: TLR001 | N10: Telur | O10: Sembako | P10: kilo | Q10: 10 | S10: 285000 | T10: 9 | U10: - | V10: -
A11: 45293 | B11: {=IF(C11="","", IFERROR(INDEX(Barang!$A$2:$A$10001, MATCH(C11, Barang!$B$2:$B$10001, 0)), "Tidak ditemukan"))} -> BKT001 | C11: Biskuat | D11: {=IF(C11="","", IFERROR(INDEX(Barang!$C$2:$C$10001, MATCH(C11, Barang!$B$2:$B$10001, 0)), ""))} -> Makanan | E11: {=IF(C11="","", IFERROR(INDEX(Barang!$E$2:$E$10001, MATCH(C11, Barang!$B$2:$B$10001, 0)), ""))} -> pcs | F11: 40 | G11: {=IF(C11="","", IFERROR(INDEX(Barang!$F$2:$F$10001, MATCH(C11, Barang!$B$2:$B$10001, 0)) * F11, ""))} -> 20000 | L11: 45293 | M11: UBM001 | N11: Mari UBM | O11: Makanan | P11: bungkus | T11: -1 | U11: - | V11: -
B12: {=IF(C12="","", IFERROR(INDEX(Barang!$A$2:$A$10001, MATCH(C12, Barang!$B$2:$B$10001, 0)), "Tidak ditemukan"))} -> TGO001 | C12: Tanggo | D12: {=IF(C12="","", IFERROR(INDEX(Barang!$C$2:$C$10001, MATCH(C12, Barang!$B$2:$B$10001, 0)), ""))} -> Makanan | E12: {=IF(C12="","", IFERROR(INDEX(Barang!$E$2:$E$10001, MATCH(C12, Barang!$B$2:$B$10001, 0)), ""))} -> pcs | F12: 20 | G12: {=IF(C12="","", IFERROR(INDEX(Barang!$F$2:$F$10001, MATCH(C12, Barang!$B$2:$B$10001, 0)) * F12, ""))} -> 40000 | M12: TGO001 | N12: Tanggo | O12: Makanan | P12: bungkus | T12: -1 | U12: - | V12: -
B13: {=IF(C13="","", IFERROR(INDEX(Barang!$A$2:$A$10001, MATCH(C13, Barang!$B$2:$B$10001, 0)), "Tidak ditemukan"))} -> CL1001 | C13: Chocolatos 1000 | D13: {=IF(C13="","", IFERROR(INDEX(Barang!$C$2:$C$10001, MATCH(C13, Barang!$B$2:$B$10001, 0)), ""))} -> Makanan | E13: {=IF(C13="","", IFERROR(INDEX(Barang!$E$2:$E$10001, MATCH(C13, Barang!$B$2:$B$10001, 0)), ""))} -> pcs | F13: 24 | G13: {=IF(C13="","", IFERROR(INDEX(Barang!$F$2:$F$10001, MATCH(C13, Barang!$B$2:$B$10001, 0)) * F13, ""))} -> 24000 | M13: CCS001 | N13: Chocolatos | O13: Makanan | P13: bungkus | Q13: 120 | S13: 60000 | T13: 119 | U13: - | V13: -
B14: {=IF(C14="","", IFERROR(INDEX(Barang!$A$2:$A$10001, MATCH(C14, Barang!$B$2:$B$10001, 0)), "Tidak ditemukan"))} -> GRM01 | C14: Garam | D14: {=IF(C14="","", IFERROR(INDEX(Barang!$C$2:$C$10001, MATCH(C14, Barang!$B$2:$B$10001, 0)), ""))} -> Bumbu | E14: {=IF(C14="","", IFERROR(INDEX(Barang!$E$2:$E$10001, MATCH(C14, Barang!$B$2:$B$10001, 0)), ""))} -> pcs | F14: 15 | G14: {=IF(C14="","", IFERROR(INDEX(Barang!$F$2:$F$10001, MATCH(C14, Barang!$B$2:$B$10001, 0)) * F14, ""))} -> 37500 | M14: GRM001 | N14: Garam | O14: Bumbu | P14: bungkus | Q14: 40 | S14: 67000 | T14: 39 | U14: - | V14: -
B15: {=IF(C15="","", IFERROR(INDEX(Barang!$A$2:$A$10001, MATCH(C15, Barang!$B$2:$B$10001, 0)), "Tidak ditemukan"))} -> RYC001 | C15: Royco | D15: {=IF(C15="","", IFERROR(INDEX(Barang!$C$2:$C$10001, MATCH(C15, Barang!$B$2:$B$10001, 0)), ""))} -> Bumbu | E15: {=IF(C15="","", IFERROR(INDEX(Barang!$E$2:$E$10001, MATCH(C15, Barang!$B$2:$B$10001, 0)), ""))} -> pcs | F15: 24 | G15: {=IF(C15="","", IFERROR(INDEX(Barang!$F$2:$F$10001, MATCH(C15, Barang!$B$2:$B$10001, 0)) * F15, ""))} -> 12000 | M15: RYC001 | N15: Royco | O15: Bumbu | P15: bungkus | Q15: 36 | S15: 14500 | T15: -4 | U15: - | V15: -
B16: {=IF(C16="","", IFERROR(INDEX(Barang!$A$2:$A$10001, MATCH(C16, Barang!$B$2:$B$10001, 0)), "Tidak ditemukan"))} -> KPH001 | C16: Kopi hitam | D16: {=IF(C16="","", IFERROR(INDEX(Barang!$C$2:$C$10001, MATCH(C16, Barang!$B$2:$B$10001, 0)), ""))} -> Minuman | E16: {=IF(C16="","", IFERROR(INDEX(Barang!$E$2:$E$10001, MATCH(C16, Barang!$B$2:$B$10001, 0)), ""))} -> pcs | F16: 34 | G16: {=IF(C16="","", IFERROR(INDEX(Barang!$F$2:$F$10001, MATCH(C16, Barang!$B$2:$B$10001, 0)) * F16, ""))} -> 34000 | M16: KP001 | N16: Kopi k.a | O16: Minuman | P16: bungkus | T16: -10 | U16: - | V16: -
B17: {=IF(C17="","", IFERROR(INDEX(Barang!$A$2:$A$10001, MATCH(C17, Barang!$B$2:$B$10001, 0)), "Tidak ditemukan"))} -> MKH001 | C17: Mie kuah | D17: {=IF(C17="","", IFERROR(INDEX(Barang!$C$2:$C$10001, MATCH(C17, Barang!$B$2:$B$10001, 0)), ""))} -> Makanan | E17: {=IF(C17="","", IFERROR(INDEX(Barang!$E$2:$E$10001, MATCH(C17, Barang!$B$2:$B$10001, 0)), ""))} -> pcs | F17: 18 | G17: {=IF(C17="","", IFERROR(INDEX(Barang!$F$2:$F$10001, MATCH(C17, Barang!$B$2:$B$10001, 0)) * F17, ""))} -> 63000 | M17: MKH001 | N17: Mie kuah | O17: Makanan | P17: bungkus | Q17: 20 | S17: 53000 | T17: 19 | U17: - | V17: -
B18: {=IF(C18="","", IFERROR(INDEX(Barang!$A$2:$A$10001, MATCH(C18, Barang!$B$2:$B$10001, 0)), "Tidak ditemukan"))} -> CLB001 | C18: Chocolatos bubuk | D18: {=IF(C18="","", IFERROR(INDEX(Barang!$C$2:$C$10001, MATCH(C18, Barang!$B$2:$B$10001, 0)), ""))} -> Minuman | E18: {=IF(C18="","", IFERROR(INDEX(Barang!$E$2:$E$10001, MATCH(C18, Barang!$B$2:$B$10001, 0)), ""))} -> pcs | F18: 37 | G18: {=IF(C18="","", IFERROR(INDEX(Barang!$F$2:$F$10001, MATCH(C18, Barang!$B$2:$B$10001, 0)) * F18, ""))} -> 92500 | M18: CCSB001 | N18: Chocolatos bubuk | O18: Minuman | P18: bungkus | Q18: 20 | S18: 35000 | T18: 19 | U18: - | V18: -
B19: {=IF(C19="","", IFERROR(INDEX(Barang!$A$2:$A$10001, MATCH(C19, Barang!$B$2:$B$10001, 0)), "Tidak ditemukan"))} -> GL1001 | C19: Gula 1kg | D19: {=IF(C19="","", IFERROR(INDEX(Barang!$C$2:$C$10001, MATCH(C19, Barang!$B$2:$B$10001, 0)), ""))} -> Sembako | E19: {=IF(C19="","", IFERROR(INDEX(Barang!$E$2:$E$10001, MATCH(C19, Barang!$B$2:$B$10001, 0)), ""))} -> kg | F19: 20 | G19: {=IF(C19="","", IFERROR(INDEX(Barang!$F$2:$F$10001, MATCH(C19, Barang!$B$2:$B$10001, 0)) * F19, ""))} -> 330000 | M19: GL001 | N19: Gula | O19: Sembako | P19: kilo | Q19: 10 | S19: 125000 | T19: 9 | U19: - | V19: -
B20: {=IF(C20="","", IFERROR(INDEX(Barang!$A$2:$A$10001, MATCH(C20, Barang!$B$2:$B$10001, 0)), "Tidak ditemukan"))} -> NTS001 | C20: Nutrisari | D20: {=IF(C20="","", IFERROR(INDEX(Barang!$C$2:$C$10001, MATCH(C20, Barang!$B$2:$B$10001, 0)), ""))} -> Minuman | E20: {=IF(C20="","", IFERROR(INDEX(Barang!$E$2:$E$10001, MATCH(C20, Barang!$B$2:$B$10001, 0)), ""))} -> pcs | F20: 12 | G20: {=IF(C20="","", IFERROR(INDEX(Barang!$F$2:$F$10001, MATCH(C20, Barang!$B$2:$B$10001, 0)) * F20, ""))} -> 18000 | M20: NTS001 | N20: Nutrisari | O20: Minuman | P20: bungkus | Q20: 70 | S20: 84000 | T20: -3 | U20: - | V20: -
B21: {=IF(C21="","", IFERROR(INDEX(Barang!$A$2:$A$10001, MATCH(C21, Barang!$B$2:$B$10001, 0)), "Tidak ditemukan"))} -> MGR001 | C21: MIE GORENG | D21: {=IF(C21="","", IFERROR(INDEX(Barang!$C$2:$C$10001, MATCH(C21, Barang!$B$2:$B$10001, 0)), ""))} -> Makanan | E21: {=IF(C21="","", IFERROR(INDEX(Barang!$E$2:$E$10001, MATCH(C21, Barang!$B$2:$B$10001, 0)), ""))} -> pcs | F21: 20 | G21: {=IF(C21="","", IFERROR(INDEX(Barang!$F$2:$F$10001, MATCH(C21, Barang!$B$2:$B$10001, 0)) * F21, ""))} -> 70000 | M21: STN001 | N21: Santan | O21: Bumbu | P21: bungkus | T21: -1 | U21: - | V21: -
B22: {=IF(C22="","", IFERROR(INDEX(Barang!$A$2:$A$10001, MATCH(C22, Barang!$B$2:$B$10001, 0)), "Tidak ditemukan"))} -> TLR2 | C22: Telur 1/2 | D22: {=IF(C22="","", IFERROR(INDEX(Barang!$C$2:$C$10001, MATCH(C22, Barang!$B$2:$B$10001, 0)), ""))} -> Sembako | E22: {=IF(C22="","", IFERROR(INDEX(Barang!$E$2:$E$10001, MATCH(C22, Barang!$B$2:$B$10001, 0)), ""))} -> kg | F22: 15 | G22: {=IF(C22="","", IFERROR(INDEX(Barang!$F$2:$F$10001, MATCH(C22, Barang!$B$2:$B$10001, 0)) * F22, ""))} -> 232500 | M22: TLR001 | N22: Telur | O22: Sembako | P22: kilo | Q22: 10 | S22: 282000 | T22: 26/11 | U22: - | V22: -
B23: {=IF(C23="","", IFERROR(INDEX(Barang!$A$2:$A$10001, MATCH(C23, Barang!$B$2:$B$10001, 0)), "Tidak ditemukan"))} -> GDY001 | C23: Good day | D23: {=IF(C23="","", IFERROR(INDEX(Barang!$C$2:$C$10001, MATCH(C23, Barang!$B$2:$B$10001, 0)), ""))} -> Minuman | E23: {=IF(C23="","", IFERROR(INDEX(Barang!$E$2:$E$10001, MATCH(C23, Barang!$B$2:$B$10001, 0)), ""))} -> pcs | F23: 10 | G23: {=IF(C23="","", IFERROR(INDEX(Barang!$F$2:$F$10001, MATCH(C23, Barang!$B$2:$B$10001, 0)) * F23, ""))} -> 25000 | M23: GDY001 | N23: GoodDay | O23: Minuman | P23: bungkus | Q23: 20 | S23: 42000 | T23: 19 | U23: - | V23: -
B24: {=IF(C24="","", IFERROR(INDEX(Barang!$A$2:$A$10001, MATCH(C24, Barang!$B$2:$B$10001, 0)), "Tidak ditemukan"))} -> PLS002 | C24: pilus | D24: {=IF(C24="","", IFERROR(INDEX(Barang!$C$2:$C$10001, MATCH(C24, Barang!$B$2:$B$10001, 0)), ""))} -> Makanan | E24: {=IF(C24="","", IFERROR(INDEX(Barang!$E$2:$E$10001, MATCH(C24, Barang!$B$2:$B$10001, 0)), ""))} -> pcs | F24: 20 | G24: {=IF(C24="","", IFERROR(INDEX(Barang!$F$2:$F$10001, MATCH(C24, Barang!$B$2:$B$10001, 0)) * F24, ""))} -> 20000 | M24: PLS001 | N24: Pilus garuda | O24: Makanan | P24: bungkus | Q24: 20 | S24: 16000 | T24: -4 | U24: - | V24: -
B25: {=IF(C25="","", IFERROR(INDEX(Barang!$A$2:$A$10001, MATCH(C25, Barang!$B$2:$B$10001, 0)), "Tidak ditemukan"))} -> YP500 | C25: Yupi 500 | D25: {=IF(C25="","", IFERROR(INDEX(Barang!$C$2:$C$10001, MATCH(C25, Barang!$B$2:$B$10001, 0)), ""))} -> Makanan | E25: {=IF(C25="","", IFERROR(INDEX(Barang!$E$2:$E$10001, MATCH(C25, Barang!$B$2:$B$10001, 0)), ""))} -> pcs | F25: 72 | G25: {=IF(C25="","", IFERROR(INDEX(Barang!$F$2:$F$10001, MATCH(C25, Barang!$B$2:$B$10001, 0)) * F25, ""))} -> 36000 | I25: =SUM(G11:G25) -> 1054500 | M25: PYP001 | N25: Permen Yupi | O25: Makanan | P25: bungkus | Q25: 288 | S25: 120000 | T25: 286 | U25: - | V25: -
A26: 45294 | B26: {=IF(C26="","", IFERROR(INDEX(Barang!$A$2:$A$10001, MATCH(C26, Barang!$B$2:$B$10001, 0)), "Tidak ditemukan"))} -> RCK001 | C26: racik | D26: {=IF(C26="","", IFERROR(INDEX(Barang!$C$2:$C$10001, MATCH(C26, Barang!$B$2:$B$10001, 0)), ""))} -> Bumbu | E26: {=IF(C26="","", IFERROR(INDEX(Barang!$E$2:$E$10001, MATCH(C26, Barang!$B$2:$B$10001, 0)), ""))} -> pcs | F26: 11 | G26: {=IF(C26="","", IFERROR(INDEX(Barang!$F$2:$F$10001, MATCH(C26, Barang!$B$2:$B$10001, 0)) * F26, ""))} -> 22000 | L26: 45294 | M26: RCK001 | N26: Racik | O26: Bumbu | P26: bungkus | Q26: 20 | S26: 33000 | T26: 19 | U26: - | V26: -
B27: {=IF(C27="","", IFERROR(INDEX(Barang!$A$2:$A$10001, MATCH(C27, Barang!$B$2:$B$10001, 0)), "Tidak ditemukan"))} -> YP500 | C27: YUPI 500 | D27: {=IF(C27="","", IFERROR(INDEX(Barang!$C$2:$C$10001, MATCH(C27, Barang!$B$2:$B$10001, 0)), ""))} -> Makanan | E27: {=IF(C27="","", IFERROR(INDEX(Barang!$E$2:$E$10001, MATCH(C27, Barang!$B$2:$B$10001, 0)), ""))} -> pcs | F27: 48 | G27: {=IF(C27="","", IFERROR(INDEX(Barang!$F$2:$F$10001, MATCH(C27, Barang!$B$2:$B$10001, 0)) * F27, ""))} -> 24000 | M27: KRS001 | N27: Kara Santan | O27: Bumbu | P27: bungkus | Q27: 15 | S27: 86500 | T27: 14 | U27: - | V27: -
B28: {=IF(C28="","", IFERROR(INDEX(Barang!$A$2:$A$10001, MATCH(C28, Barang!$B$2:$B$10001, 0)), "Tidak ditemukan"))} -> MSK001 | C28: Masako | D28: {=IF(C28="","", IFERROR(INDEX(Barang!$C$2:$C$10001, MATCH(C28, Barang!$B$2:$B$10001, 0)), ""))} -> Bumbu | E28: {=IF(C28="","", IFERROR(INDEX(Barang!$E$2:$E$10001, MATCH(C28, Barang!$B$2:$B$10001, 0)), ""))} -> pcs | F28: 15 | G28: {=IF(C28="","", IFERROR(INDEX(Barang!$F$2:$F$10001, MATCH(C28, Barang!$B$2:$B$10001, 0)) * F28, ""))} -> 7500 | M28: MSK001 | N28: Masako | O28: Bumbu | P28: bungkus | Q28: 72 | S28: 27000 | T28: 71 | U28: - | V28: -
B29: {=IF(C29="","", IFERROR(INDEX(Barang!$A$2:$A$10001, MATCH(C29, Barang!$B$2:$B$10001, 0)), "Tidak ditemukan"))} -> LDK001 | C29: Ladaku | D29: {=IF(C29="","", IFERROR(INDEX(Barang!$C$2:$C$10001, MATCH(C29, Barang!$B$2:$B$10001, 0)), ""))} -> Bumbu | E29: {=IF(C29="","", IFERROR(INDEX(Barang!$E$2:$E$10001, MATCH(C29, Barang!$B$2:$B$10001, 0)), ""))} -> pcs | F29: 8 | G29: {=IF(C29="","", IFERROR(INDEX(Barang!$F$2:$F$10001, MATCH(C29, Barang!$B$2:$B$10001, 0)) * F29, ""))} -> 8000 | M29: LDB001 | N29: Lada Bubuk | O29: Bumbu | P29: bungkus | T29: -1 | U29: - | V29: -
B30: {=IF(C30="","", IFERROR(INDEX(Barang!$A$2:$A$10001, MATCH(C30, Barang!$B$2:$B$10001, 0)), "Tidak ditemukan"))} -> BPT1 | C30: B. putih 1/4 | D30: {=IF(C30="","", IFERROR(INDEX(Barang!$C$2:$C$10001, MATCH(C30, Barang!$B$2:$B$10001, 0)), ""))} -> Rempah | E30: {=IF(C30="","", IFERROR(INDEX(Barang!$E$2:$E$10001, MATCH(C30, Barang!$B$2:$B$10001, 0)), ""))} -> kg | F30: 6 | G30: {=IF(C30="","", IFERROR(INDEX(Barang!$F$2:$F$10001, MATCH(C30, Barang!$B$2:$B$10001, 0)) * F30, ""))} -> 51000 | M30: BPT001 | N30: Bawang Putih | O30: Rempah | P30: kilo | Q30: 2 | S30: 76000 | T30: 30/9 | U30: - | V30: -
B31: {=IF(C31="","", IFERROR(INDEX(Barang!$A$2:$A$10001, MATCH(C31, Barang!$B$2:$B$10001, 0)), "Tidak ditemukan"))} -> YP1001 | C31: yupi 1000 | D31: {=IF(C31="","", IFERROR(INDEX(Barang!$C$2:$C$10001, MATCH(C31, Barang!$B$2:$B$10001, 0)), ""))} -> Makanan | E31: {=IF(C31="","", IFERROR(INDEX(Barang!$E$2:$E$10001, MATCH(C31, Barang!$B$2:$B$10001, 0)), ""))} -> pcs | F31: 25 | G31: {=IF(C31="","", IFERROR(INDEX(Barang!$F$2:$F$10001, MATCH(C31, Barang!$B$2:$B$10001, 0)) * F31, ""))} -> 25000 | M31: PYP001 | N31: Permen Yupi | O31: Makanan | P31: bungkus | Q31: 288 | S31: 120000 | T31: 280 | U31: - | V31: -
B32: {=IF(C32="","", IFERROR(INDEX(Barang!$A$2:$A$10001, MATCH(C32, Barang!$B$2:$B$10001, 0)), "Tidak ditemukan"))} -> MGR001 | C32: Mie Goreng | D32: {=IF(C32="","", IFERROR(INDEX(Barang!$C$2:$C$10001, MATCH(C32, Barang!$B$2:$B$10001, 0)), ""))} -> Makanan | E32: {=IF(C32="","", IFERROR(INDEX(Barang!$E$2:$E$10001, MATCH(C32, Barang!$B$2:$B$10001, 0)), ""))} -> pcs | F32: 94 | G32: {=IF(C32="","", IFERROR(INDEX(Barang!$F$2:$F$10001, MATCH(C32, Barang!$B$2:$B$10001, 0)) * F32, ""))} -> 329000 | M32: MGR001 | N32: Mie Goreng | O32: Makanan | P32: bungkus | Q32: 20 | S32: 56000 | T32: 18 | U32: - | V32: -
B33: {=IF(C33="","", IFERROR(INDEX(Barang!$A$2:$A$10001, MATCH(C33, Barang!$B$2:$B$10001, 0)), "Tidak ditemukan"))} -> MP001 | C33: Mie Panda | D33: {=IF(C33="","", IFERROR(INDEX(Barang!$C$2:$C$10001, MATCH(C33, Barang!$B$2:$B$10001, 0)), ""))} -> Makanan | E33: {=IF(C33="","", IFERROR(INDEX(Barang!$E$2:$E$10001, MATCH(C33, Barang!$B$2:$B$10001, 0)), ""))} -> pcs | F33: 27 | G33: {=IF(C33="","", IFERROR(INDEX(Barang!$F$2:$F$10001, MATCH(C33, Barang!$B$2:$B$10001, 0)) * F33, ""))} -> 162000 | M33: MPD001 | N33: Mie Panda | O33: Makanan | P33: bungkus | T33: -1 | U33: - | V33: -
B34: {=IF(C34="","", IFERROR(INDEX(Barang!$A$2:$A$10001, MATCH(C34, Barang!$B$2:$B$10001, 0)), "Tidak ditemukan"))} -> TGB01 | C34: Tepung bakwan | D34: {=IF(C34="","", IFERROR(INDEX(Barang!$C$2:$C$10001, MATCH(C34, Barang!$B$2:$B$10001, 0)), ""))} -> Bumbu | E34: {=IF(C34="","", IFERROR(INDEX(Barang!$E$2:$E$10001, MATCH(C34, Barang!$B$2:$B$10001, 0)), ""))} -> pcs | F34: 38 | G34: {=IF(C34="","", IFERROR(INDEX(Barang!$F$2:$F$10001, MATCH(C34, Barang!$B$2:$B$10001, 0)) * F34, ""))} -> 95000 | M34: TPG001 | N34: Tepung Geprek | O34: Bumbu mix | P34: bungkus | T34: -1 | U34: - | V34: -
B35: {=IF(C35="","", IFERROR(INDEX(Barang!$A$2:$A$10001, MATCH(C35, Barang!$B$2:$B$10001, 0)), "Tidak ditemukan"))} -> TGJ001 | C35: Tepung Jempol | D35: {=IF(C35="","", IFERROR(INDEX(Barang!$C$2:$C$10001, MATCH(C35, Barang!$B$2:$B$10001, 0)), ""))} -> Bumbu | E35: {=IF(C35="","", IFERROR(INDEX(Barang!$E$2:$E$10001, MATCH(C35, Barang!$B$2:$B$10001, 0)), ""))} -> pcs | F35: 24 | G35: {=IF(C35="","", IFERROR(INDEX(Barang!$F$2:$F$10001, MATCH(C35, Barang!$B$2:$B$10001, 0)) * F35, ""))} -> 72000 | M35: TPJ001 | N35: Tepung Jempol | O35: Bumbu mix | P35: bungkus | Q35: 10 | S35: 22000 | T35: 9 | U35: - | V35: -
B36: {=IF(C36="","", IFERROR(INDEX(Barang!$A$2:$A$10001, MATCH(C36, Barang!$B$2:$B$10001, 0)), "Tidak ditemukan"))} -> SDK001 | C36: Sedaap kaldu | D36: {=IF(C36="","", IFERROR(INDEX(Barang!$C$2:$C$10001, MATCH(C36, Barang!$B$2:$B$10001, 0)), ""))} -> Bumbu | E36: {=IF(C36="","", IFERROR(INDEX(Barang!$E$2:$E$10001, MATCH(C36, Barang!$B$2:$B$10001, 0)), ""))} -> pcs | F36: 30 | G36: {=IF(C36="","", IFERROR(INDEX(Barang!$F$2:$F$10001, MATCH(C36, Barang!$B$2:$B$10001, 0)) * F36, ""))} -> 15000 | M36: SDPB001 | N36: Sedaap Bumbu | O36: Bumbu | P36: bungkus | Q36: 192 | S36: 304000 | T36: 189 | U36: - | V36: -
B37: {=IF(C37="","", IFERROR(INDEX(Barang!$A$2:$A$10001, MATCH(C37, Barang!$B$2:$B$10001, 0)), "Tidak ditemukan"))} -> MKH001 | C37: mie kuah | D37: {=IF(C37="","", IFERROR(INDEX(Barang!$C$2:$C$10001, MATCH(C37, Barang!$B$2:$B$10001, 0)), ""))} -> Makanan | E37: {=IF(C37="","", IFERROR(INDEX(Barang!$E$2:$E$10001, MATCH(C37, Barang!$B$2:$B$10001, 0)), ""))} -> pcs | F37: 25 | G37: {=IF(C37="","", IFERROR(INDEX(Barang!$F$2:$F$10001, MATCH(C37, Barang!$B$2:$B$10001, 0)) * F37, ""))} -> 87500 | M37: CCS001 | N37: Chocolatos | O37: Makanan | P37: bungkus | Q37: 96 | S37: 105000 | T37: 94 | U37: - | V37: -
B38: {=IF(C38="","", IFERROR(INDEX(Barang!$A$2:$A$10001, MATCH(C38, Barang!$B$2:$B$10001, 0)), "Tidak ditemukan"))} -> PLS002 | C38: Pilus | D38: {=IF(C38="","", IFERROR(INDEX(Barang!$C$2:$C$10001, MATCH(C38, Barang!$B$2:$B$10001, 0)), ""))} -> Makanan | E38: {=IF(C38="","", IFERROR(INDEX(Barang!$E$2:$E$10001, MATCH(C38, Barang!$B$2:$B$10001, 0)), ""))} -> pcs | F38: 25 | G38: {=IF(C38="","", IFERROR(INDEX(Barang!$F$2:$F$10001, MATCH(C38, Barang!$B$2:$B$10001, 0)) * F38, ""))} -> 25000 | M38: PLS001 | N38: Pilus garuda | O38: Makanan | P38: bungkus | T38: -1 | U38: - | V38: -
B39: {=IF(C39="","", IFERROR(INDEX(Barang!$A$2:$A$10001, MATCH(C39, Barang!$B$2:$B$10001, 0)), "Tidak ditemukan"))} -> LML002 | C39: Le mineral | D39: {=IF(C39="","", IFERROR(INDEX(Barang!$C$2:$C$10001, MATCH(C39, Barang!$B$2:$B$10001, 0)), ""))} -> Minuman | E39: {=IF(C39="","", IFERROR(INDEX(Barang!$E$2:$E$10001, MATCH(C39, Barang!$B$2:$B$10001, 0)), ""))} -> btl | F39: 40 | G39: {=IF(C39="","", IFERROR(INDEX(Barang!$F$2:$F$10001, MATCH(C39, Barang!$B$2:$B$10001, 0)) * F39, ""))} -> 760000 | M39: LMR001 | N39: Le mineral | O39: Minuman | P39: botol | T39: -1 | U39: - | V39: -
B40: {=IF(C40="","", IFERROR(INDEX(Barang!$A$2:$A$10001, MATCH(C40, Barang!$B$2:$B$10001, 0)), "Tidak ditemukan"))} -> DTL001 | C40: Detol | D40: {=IF(C40="","", IFERROR(INDEX(Barang!$C$2:$C$10001, MATCH(C40, Barang!$B$2:$B$10001, 0)), ""))} -> Sabun | E40: {=IF(C40="","", IFERROR(INDEX(Barang!$E$2:$E$10001, MATCH(C40, Barang!$B$2:$B$10001, 0)), ""))} -> pcs | F40: 16 | G40: {=IF(C40="","", IFERROR(INDEX(Barang!$F$2:$F$10001, MATCH(C40, Barang!$B$2:$B$10001, 0)) * F40, ""))} -> 112000 | M40: DTL001 | N40: Detol | O40: Sabun | P40: bungkus | Q40: 5 | S40: 31500 | T40: 4 | U40: - | V40: -
...

Sheet 2025
A1: Tanggal | B1: Kode Barang | C1: Nama Barang | D1: Kategori | E1: Satuan | F1: Jual | G1: Harga Jual | H1: Stok Awal | I1: Total | J1: Column 1 | L1: Tanggal | M1: Kode Barang | N1: Nama Barang | O1: Kategori | P1: Satuan | Q1: Kulak | R1: Harga Jual | S1: Harga Kulak | T1: Stok Akhir | U1: Minimal Stok | V1: Supplier
A2: 45938 | B2: {=IF(C2="","", IFERROR(INDEX(Barang!$A$2:$A$10001, MATCH(C2, Barang!$B$2:$B$10001, 0)), "Tidak ditemukan"))} -> ADS001 | C2: Adem Sari | D2: {=IF(C2="","", IFERROR(INDEX(Barang!$C$2:$C$10001, MATCH(C2, Barang!$B$2:$B$10001, 0)), ""))} -> Minuman | E2: {=IF(C2="","", IFERROR(INDEX(Barang!$E$2:$E$10001, MATCH(C2, Barang!$B$2:$B$10001, 0)), ""))} -> pcs | F2: 30 | G2: {=IF(C2="","", IFERROR(INDEX(Barang!$F$2:$F$10001, MATCH(C2, Barang!$B$2:$B$10001, 0)) * F2, ""))} -> 75000 | M2: {=IF(N2="","", IFERROR(INDEX(Barang!$A$2:$A$10001, MATCH(N2, Barang!$B$2:$B$10001, 0)), "Tidak ditemukan"))} | O2: {=IF(N2="","", IFERROR(INDEX(Barang!$C$2:$C$10001, MATCH(N2, Barang!$B$2:$B$10001, 0)), ""))} | P2: {=IF(N2="","", IFERROR(INDEX(Barang!$E$2:$E$10001, MATCH(N2, Barang!$B$2:$B$10001, 0)), ""))} | R2: {=IF(N2="","", IFERROR(INDEX(Barang!$F$2:$F$10001, MATCH(N2, Barang!$B$2:$B$10001, 0)) * Q2, ""))} | U2: - | V2: -
B3: {=IF(C3="","", IFERROR(INDEX(Barang!$A$2:$A$10001, MATCH(C3, Barang!$B$2:$B$10001, 0)), "Tidak ditemukan"))} -> TPL2 | C3: Tropical 2Lt | D3: {=IF(C3="","", IFERROR(INDEX(Barang!$C$2:$C$10001, MATCH(C3, Barang!$B$2:$B$10001, 0)), ""))} -> Minyak | E3: {=IF(C3="","", IFERROR(INDEX(Barang!$E$2:$E$10001, MATCH(C3, Barang!$B$2:$B$10001, 0)), ""))} -> Liter | F3: 10 | G3: {=IF(C3="","", IFERROR(INDEX(Barang!$F$2:$F$10001, MATCH(C3, Barang!$B$2:$B$10001, 0)) * F3, ""))} -> 400000 | M3: {=IF(N3="","", IFERROR(INDEX(Barang!$A$2:$A$10001, MATCH(N3, Barang!$B$2:$B$10001, 0)), "Tidak ditemukan"))} | O3: {=IF(N3="","", IFERROR(INDEX(Barang!$C$2:$C$10001, MATCH(N3, Barang!$B$2:$B$10001, 0)), ""))} | P3: {=IF(N3="","", IFERROR(INDEX(Barang!$E$2:$E$10001, MATCH(N3, Barang!$B$2:$B$10001, 0)), ""))} | R3: {=IF(N3="","", IFERROR(INDEX(Barang!$F$2:$F$10001, MATCH(N3, Barang!$B$2:$B$10001, 0)) * Q3, ""))} | U3: - | V3: -
B4: {=IF(C4="","", IFERROR(INDEX(Barang!$A$2:$A$10001, MATCH(C4, Barang!$B$2:$B$10001, 0)), "Tidak ditemukan"))} -> LFB001 | C4: Lifebouy | D4: {=IF(C4="","", IFERROR(INDEX(Barang!$C$2:$C$10001, MATCH(C4, Barang!$B$2:$B$10001, 0)), ""))} -> Sabun | E4: {=IF(C4="","", IFERROR(INDEX(Barang!$E$2:$E$10001, MATCH(C4, Barang!$B$2:$B$10001, 0)), ""))} -> pcs | F4: 30 | G4: {=IF(C4="","", IFERROR(INDEX(Barang!$F$2:$F$10001, MATCH(C4, Barang!$B$2:$B$10001, 0)) * F4, ""))} -> 180000 | M4: {=IF(N4="","", IFERROR(INDEX(Barang!$A$2:$A$10001, MATCH(N4, Barang!$B$2:$B$10001, 0)), "Tidak ditemukan"))} | O4: {=IF(N4="","", IFERROR(INDEX(Barang!$C$2:$C$10001, MATCH(N4, Barang!$B$2:$B$10001, 0)), ""))} | P4: {=IF(N4="","", IFERROR(INDEX(Barang!$E$2:$E$10001, MATCH(N4, Barang!$B$2:$B$10001, 0)), ""))} | R4: {=IF(N4="","", IFERROR(INDEX(Barang!$F$2:$F$10001, MATCH(N4, Barang!$B$2:$B$10001, 0)) * Q4, ""))} | U4: - | V4: -
B5: {=IF(C5="","", IFERROR(INDEX(Barang!$A$2:$A$10001, MATCH(C5, Barang!$B$2:$B$10001, 0)), "Tidak ditemukan"))} -> TSP001 | C5: Tisu peony | D5: {=IF(C5="","", IFERROR(INDEX(Barang!$C$2:$C$10001, MATCH(C5, Barang!$B$2:$B$10001, 0)), ""))} -> Tissue | E5: {=IF(C5="","", IFERROR(INDEX(Barang!$E$2:$E$10001, MATCH(C5, Barang!$B$2:$B$10001, 0)), ""))} -> pcs | F5: 21 | G5: {=IF(C5="","", IFERROR(INDEX(Barang!$F$2:$F$10001, MATCH(C5, Barang!$B$2:$B$10001, 0)) * F5, ""))} -> 147000 | M5: {=IF(N5="","", IFERROR(INDEX(Barang!$A$2:$A$10001, MATCH(N5, Barang!$B$2:$B$10001, 0)), "Tidak ditemukan"))} | O5: {=IF(N5="","", IFERROR(INDEX(Barang!$C$2:$C$10001, MATCH(N5, Barang!$B$2:$B$10001, 0)), ""))} | P5: {=IF(N5="","", IFERROR(INDEX(Barang!$E$2:$E$10001, MATCH(N5, Barang!$B$2:$B$10001, 0)), ""))} | R5: {=IF(N5="","", IFERROR(INDEX(Barang!$F$2:$F$10001, MATCH(N5, Barang!$B$2:$B$10001, 0)) * Q5, ""))} | U5: - | V5: -
B6: {=IF(C6="","", IFERROR(INDEX(Barang!$A$2:$A$10001, MATCH(C6, Barang!$B$2:$B$10001, 0)), "Tidak ditemukan"))} -> SAR001 | C6: Saori | D6: {=IF(C6="","", IFERROR(INDEX(Barang!$C$2:$C$10001, MATCH(C6, Barang!$B$2:$B$10001, 0)), ""))} -> Bumbu | E6: {=IF(C6="","", IFERROR(INDEX(Barang!$E$2:$E$10001, MATCH(C6, Barang!$B$2:$B$10001, 0)), ""))} -> pcs | F6: 32 | G6: {=IF(C6="","", IFERROR(INDEX(Barang!$F$2:$F$10001, MATCH(C6, Barang!$B$2:$B$10001, 0)) * F6, ""))} -> 96000 | I6: =SUM(G2:G6) -> 898000 | M6: {=IF(N6="","", IFERROR(INDEX(Barang!$A$2:$A$10001, MATCH(N6, Barang!$B$2:$B$10001, 0)), "Tidak ditemukan"))} | O6: {=IF(N6="","", IFERROR(INDEX(Barang!$C$2:$C$10001, MATCH(N6, Barang!$B$2:$B$10001, 0)), ""))} | P6: {=IF(N6="","", IFERROR(INDEX(Barang!$E$2:$E$10001, MATCH(N6, Barang!$B$2:$B$10001, 0)), ""))} | R6: {=IF(N6="","", IFERROR(INDEX(Barang!$F$2:$F$10001, MATCH(N6, Barang!$B$2:$B$10001, 0)) * Q6, ""))} | U6: - | V6: -
A7: 45939 | B7: {=IF(C7="","", IFERROR(INDEX(Barang!$A$2:$A$10001, MATCH(C7, Barang!$B$2:$B$10001, 0)), "Tidak ditemukan"))} -> TGJ001 | C7: Tepung Jempol | D7: {=IF(C7="","", IFERROR(INDEX(Barang!$C$2:$C$10001, MATCH(C7, Barang!$B$2:$B$10001, 0)), ""))} -> Bumbu | E7: {=IF(C7="","", IFERROR(INDEX(Barang!$E$2:$E$10001, MATCH(C7, Barang!$B$2:$B$10001, 0)), ""))} -> pcs | F7: 20 | G7: {=IF(C7="","", IFERROR(INDEX(Barang!$F$2:$F$10001, MATCH(C7, Barang!$B$2:$B$10001, 0)) * F7, ""))} -> 60000 | M7: {=IF(N7="","", IFERROR(INDEX(Barang!$A$2:$A$10001, MATCH(N7, Barang!$B$2:$B$10001, 0)), "Tidak ditemukan"))} | O7: {=IF(N7="","", IFERROR(INDEX(Barang!$C$2:$C$10001, MATCH(N7, Barang!$B$2:$B$10001, 0)), ""))} | P7: {=IF(N7="","", IFERROR(INDEX(Barang!$E$2:$E$10001, MATCH(N7, Barang!$B$2:$B$10001, 0)), ""))} | R7: {=IF(N7="","", IFERROR(INDEX(Barang!$F$2:$F$10001, MATCH(N7, Barang!$B$2:$B$10001, 0)) * Q7, ""))} | U7: - | V7: -
B8: {=IF(C8="","", IFERROR(INDEX(Barang!$A$2:$A$10001, MATCH(C8, Barang!$B$2:$B$10001, 0)), "Tidak ditemukan"))} -> MGR001 | C8: Mie Goreng | D8: {=IF(C8="","", IFERROR(INDEX(Barang!$C$2:$C$10001, MATCH(C8, Barang!$B$2:$B$10001, 0)), ""))} -> Makanan | E8: {=IF(C8="","", IFERROR(INDEX(Barang!$E$2:$E$10001, MATCH(C8, Barang!$B$2:$B$10001, 0)), ""))} -> pcs | F8: 42 | G8: {=IF(C8="","", IFERROR(INDEX(Barang!$F$2:$F$10001, MATCH(C8, Barang!$B$2:$B$10001, 0)) * F8, ""))} -> 147000 | M8: {=IF(N8="","", IFERROR(INDEX(Barang!$A$2:$A$10001, MATCH(N8, Barang!$B$2:$B$10001, 0)), "Tidak ditemukan"))} | O8: {=IF(N8="","", IFERROR(INDEX(Barang!$C$2:$C$10001, MATCH(N8, Barang!$B$2:$B$10001, 0)), ""))} | P8: {=IF(N8="","", IFERROR(INDEX(Barang!$E$2:$E$10001, MATCH(N8, Barang!$B$2:$B$10001, 0)), ""))} | R8: {=IF(N8="","", IFERROR(INDEX(Barang!$F$2:$F$10001, MATCH(N8, Barang!$B$2:$B$10001, 0)) * Q8, ""))} | U8: - | V8: -
B9: {=IF(C9="","", IFERROR(INDEX(Barang!$A$2:$A$10001, MATCH(C9, Barang!$B$2:$B$10001, 0)), "Tidak ditemukan"))} -> GL1001 | C9: Gula 1kg | D9: {=IF(C9="","", IFERROR(INDEX(Barang!$C$2:$C$10001, MATCH(C9, Barang!$B$2:$B$10001, 0)), ""))} -> Sembako | E9: {=IF(C9="","", IFERROR(INDEX(Barang!$E$2:$E$10001, MATCH(C9, Barang!$B$2:$B$10001, 0)), ""))} -> kg | F9: 7 | G9: {=IF(C9="","", IFERROR(INDEX(Barang!$F$2:$F$10001, MATCH(C9, Barang!$B$2:$B$10001, 0)) * F9, ""))} -> 115500 | M9: {=IF(N9="","", IFERROR(INDEX(Barang!$A$2:$A$10001, MATCH(N9, Barang!$B$2:$B$10001, 0)), "Tidak ditemukan"))} | O9: {=IF(N9="","", IFERROR(INDEX(Barang!$C$2:$C$10001, MATCH(N9, Barang!$B$2:$B$10001, 0)), ""))} | P9: {=IF(N9="","", IFERROR(INDEX(Barang!$E$2:$E$10001, MATCH(N9, Barang!$B$2:$B$10001, 0)), ""))} | R9: {=IF(N9="","", IFERROR(INDEX(Barang!$F$2:$F$10001, MATCH(N9, Barang!$B$2:$B$10001, 0)) * Q9, ""))} | U9: - | V9: -
B10: {=IF(C10="","", IFERROR(INDEX(Barang!$A$2:$A$10001, MATCH(C10, Barang!$B$2:$B$10001, 0)), "Tidak ditemukan"))} -> RTP001 | C10: Roti Pia | D10: {=IF(C10="","", IFERROR(INDEX(Barang!$C$2:$C$10001, MATCH(C10, Barang!$B$2:$B$10001, 0)), ""))} -> Makanan | E10: {=IF(C10="","", IFERROR(INDEX(Barang!$E$2:$E$10001, MATCH(C10, Barang!$B$2:$B$10001, 0)), ""))} -> pcs | F10: 10 | G10: {=IF(C10="","", IFERROR(INDEX(Barang!$F$2:$F$10001, MATCH(C10, Barang!$B$2:$B$10001, 0)) * F10, ""))} -> 20000 | M10: {=IF(N10="","", IFERROR(INDEX(Barang!$A$2:$A$10001, MATCH(N10, Barang!$B$2:$B$10001, 0)), "Tidak ditemukan"))} | O10: {=IF(N10="","", IFERROR(INDEX(Barang!$C$2:$C$10001, MATCH(N10, Barang!$B$2:$B$10001, 0)), ""))} | P10: {=IF(N10="","", IFERROR(INDEX(Barang!$E$2:$E$10001, MATCH(N10, Barang!$B$2:$B$10001, 0)), ""))} | R10: {=IF(N10="","", IFERROR(INDEX(Barang!$F$2:$F$10001, MATCH(N10, Barang!$B$2:$B$10001, 0)) * Q10, ""))}
B11: {=IF(C11="","", IFERROR(INDEX(Barang!$A$2:$A$10001, MATCH(C11, Barang!$B$2:$B$10001, 0)), "Tidak ditemukan"))} -> SC001 | C11: Soklin Cair | D11: {=IF(C11="","", IFERROR(INDEX(Barang!$C$2:$C$10001, MATCH(C11, Barang!$B$2:$B$10001, 0)), ""))} -> Sabun | E11: {=IF(C11="","", IFERROR(INDEX(Barang!$E$2:$E$10001, MATCH(C11, Barang!$B$2:$B$10001, 0)), ""))} -> btl | F11: 10 | G11: {=IF(C11="","", IFERROR(INDEX(Barang!$F$2:$F$10001, MATCH(C11, Barang!$B$2:$B$10001, 0)) * F11, ""))} -> 90000 | I11: =SUM(G7:G11) -> 432500 | M11: {=IF(N11="","", IFERROR(INDEX(Barang!$A$2:$A$10001, MATCH(N11, Barang!$B$2:$B$10001, 0)), "Tidak ditemukan"))} | O11: {=IF(N11="","", IFERROR(INDEX(Barang!$C$2:$C$10001, MATCH(N11, Barang!$B$2:$B$10001, 0)), ""))} | P11: {=IF(N11="","", IFERROR(INDEX(Barang!$E$2:$E$10001, MATCH(N11, Barang!$B$2:$B$10001, 0)), ""))} | R11: {=IF(N11="","", IFERROR(INDEX(Barang!$F$2:$F$10001, MATCH(N11, Barang!$B$2:$B$10001, 0)) * Q11, ""))} | U11: - | V11: -
A12: 45940 | B12: {=IF(C12="","", IFERROR(INDEX(Barang!$A$2:$A$10001, MATCH(C12, Barang!$B$2:$B$10001, 0)), "Tidak ditemukan"))} -> BPT1 | C12: B. putih 1/4 | D12: {=IF(C12="","", IFERROR(INDEX(Barang!$C$2:$C$10001, MATCH(C12, Barang!$B$2:$B$10001, 0)), ""))} -> Rempah | E12: {=IF(C12="","", IFERROR(INDEX(Barang!$E$2:$E$10001, MATCH(C12, Barang!$B$2:$B$10001, 0)), ""))} -> kg | F12: 20 | G12: {=IF(C12="","", IFERROR(INDEX(Barang!$F$2:$F$10001, MATCH(C12, Barang!$B$2:$B$10001, 0)) * F12, ""))} -> 170000 | M12: {=IF(N12="","", IFERROR(INDEX(Barang!$A$2:$A$10001, MATCH(N12, Barang!$B$2:$B$10001, 0)), "Tidak ditemukan"))} | O12: {=IF(N12="","", IFERROR(INDEX(Barang!$C$2:$C$10001, MATCH(N12, Barang!$B$2:$B$10001, 0)), ""))} | P12: {=IF(N12="","", IFERROR(INDEX(Barang!$E$2:$E$10001, MATCH(N12, Barang!$B$2:$B$10001, 0)), ""))} | R12: {=IF(N12="","", IFERROR(INDEX(Barang!$F$2:$F$10001, MATCH(N12, Barang!$B$2:$B$10001, 0)) * Q12, ""))} | U12: - | V12: -
B13: {=IF(C13="","", IFERROR(INDEX(Barang!$A$2:$A$10001, MATCH(C13, Barang!$B$2:$B$10001, 0)), "Tidak ditemukan"))} -> EKC001 | C13: Ekonomi Cair | D13: {=IF(C13="","", IFERROR(INDEX(Barang!$C$2:$C$10001, MATCH(C13, Barang!$B$2:$B$10001, 0)), ""))} -> Sabun | E13: {=IF(C13="","", IFERROR(INDEX(Barang!$E$2:$E$10001, MATCH(C13, Barang!$B$2:$B$10001, 0)), ""))} -> pcs | F13: 22 | G13: {=IF(C13="","", IFERROR(INDEX(Barang!$F$2:$F$10001, MATCH(C13, Barang!$B$2:$B$10001, 0)) * F13, ""))} -> 220000 | M13: {=IF(N13="","", IFERROR(INDEX(Barang!$A$2:$A$10001, MATCH(N13, Barang!$B$2:$B$10001, 0)), "Tidak ditemukan"))} | O13: {=IF(N13="","", IFERROR(INDEX(Barang!$C$2:$C$10001, MATCH(N13, Barang!$B$2:$B$10001, 0)), ""))} | P13: {=IF(N13="","", IFERROR(INDEX(Barang!$E$2:$E$10001, MATCH(N13, Barang!$B$2:$B$10001, 0)), ""))} | R13: {=IF(N13="","", IFERROR(INDEX(Barang!$F$2:$F$10001, MATCH(N13, Barang!$B$2:$B$10001, 0)) * Q13, ""))} | U13: - | V13: -
B14: {=IF(C14="","", IFERROR(INDEX(Barang!$A$2:$A$10001, MATCH(C14, Barang!$B$2:$B$10001, 0)), "Tidak ditemukan"))} -> STS | C14: Santan Sasa | D14: {=IF(C14="","", IFERROR(INDEX(Barang!$C$2:$C$10001, MATCH(C14, Barang!$B$2:$B$10001, 0)), ""))} -> Bumbu | E14: {=IF(C14="","", IFERROR(INDEX(Barang!$E$2:$E$10001, MATCH(C14, Barang!$B$2:$B$10001, 0)), ""))} -> pcs | F14: 1 | G14: {=IF(C14="","", IFERROR(INDEX(Barang!$F$2:$F$10001, MATCH(C14, Barang!$B$2:$B$10001, 0)) * F14, ""))} -> 5500 | M14: {=IF(N14="","", IFERROR(INDEX(Barang!$A$2:$A$10001, MATCH(N14, Barang!$B$2:$B$10001, 0)), "Tidak ditemukan"))} | O14: {=IF(N14="","", IFERROR(INDEX(Barang!$C$2:$C$10001, MATCH(N14, Barang!$B$2:$B$10001, 0)), ""))} | P14: {=IF(N14="","", IFERROR(INDEX(Barang!$E$2:$E$10001, MATCH(N14, Barang!$B$2:$B$10001, 0)), ""))} | R14: {=IF(N14="","", IFERROR(INDEX(Barang!$F$2:$F$10001, MATCH(N14, Barang!$B$2:$B$10001, 0)) * Q14, ""))} | U14: - | V14: -
B15: {=IF(C15="","", IFERROR(INDEX(Barang!$A$2:$A$10001, MATCH(C15, Barang!$B$2:$B$10001, 0)), "Tidak ditemukan"))} -> DSO001 | C15: Desaku Opor | D15: {=IF(C15="","", IFERROR(INDEX(Barang!$C$2:$C$10001, MATCH(C15, Barang!$B$2:$B$10001, 0)), ""))} -> Bumbu | E15: {=IF(C15="","", IFERROR(INDEX(Barang!$E$2:$E$10001, MATCH(C15, Barang!$B$2:$B$10001, 0)), ""))} -> pcs | F15: 3 | G15: {=IF(C15="","", IFERROR(INDEX(Barang!$F$2:$F$10001, MATCH(C15, Barang!$B$2:$B$10001, 0)) * F15, ""))} -> 10500 | M15: {=IF(N15="","", IFERROR(INDEX(Barang!$A$2:$A$10001, MATCH(N15, Barang!$B$2:$B$10001, 0)), "Tidak ditemukan"))} | O15: {=IF(N15="","", IFERROR(INDEX(Barang!$C$2:$C$10001, MATCH(N15, Barang!$B$2:$B$10001, 0)), ""))} | P15: {=IF(N15="","", IFERROR(INDEX(Barang!$E$2:$E$10001, MATCH(N15, Barang!$B$2:$B$10001, 0)), ""))} | R15: {=IF(N15="","", IFERROR(INDEX(Barang!$F$2:$F$10001, MATCH(N15, Barang!$B$2:$B$10001, 0)) * Q15, ""))} | U15: - | V15: -
B16: {=IF(C16="","", IFERROR(INDEX(Barang!$A$2:$A$10001, MATCH(C16, Barang!$B$2:$B$10001, 0)), "Tidak ditemukan"))} -> IDM002 | C16: Indomilk | D16: {=IF(C16="","", IFERROR(INDEX(Barang!$C$2:$C$10001, MATCH(C16, Barang!$B$2:$B$10001, 0)), ""))} -> Minuman | E16: {=IF(C16="","", IFERROR(INDEX(Barang!$E$2:$E$10001, MATCH(C16, Barang!$B$2:$B$10001, 0)), ""))} -> pcs | F16: 31 | G16: {=IF(C16="","", IFERROR(INDEX(Barang!$F$2:$F$10001, MATCH(C16, Barang!$B$2:$B$10001, 0)) * F16, ""))} -> 46500 | I16: =SUM(G12:G16) -> 452500 | M16: {=IF(N16="","", IFERROR(INDEX(Barang!$A$2:$A$10001, MATCH(N16, Barang!$B$2:$B$10001, 0)), "Tidak ditemukan"))} | O16: {=IF(N16="","", IFERROR(INDEX(Barang!$C$2:$C$10001, MATCH(N16, Barang!$B$2:$B$10001, 0)), ""))} | P16: {=IF(N16="","", IFERROR(INDEX(Barang!$E$2:$E$10001, MATCH(N16, Barang!$B$2:$B$10001, 0)), ""))} | R16: {=IF(N16="","", IFERROR(INDEX(Barang!$F$2:$F$10001, MATCH(N16, Barang!$B$2:$B$10001, 0)) * Q16, ""))} | U16: - | V16: -
A17: 45941 | B17: {=IF(C17="","", IFERROR(INDEX(Barang!$A$2:$A$10001, MATCH(C17, Barang!$B$2:$B$10001, 0)), "Tidak ditemukan"))} -> MSK001 | C17: Masako | D17: {=IF(C17="","", IFERROR(INDEX(Barang!$C$2:$C$10001, MATCH(C17, Barang!$B$2:$B$10001, 0)), ""))} -> Bumbu | E17: {=IF(C17="","", IFERROR(INDEX(Barang!$E$2:$E$10001, MATCH(C17, Barang!$B$2:$B$10001, 0)), ""))} -> pcs | F17: 50 | G17: {=IF(C17="","", IFERROR(INDEX(Barang!$F$2:$F$10001, MATCH(C17, Barang!$B$2:$B$10001, 0)) * F17, ""))} -> 25000 | M17: {=IF(N17="","", IFERROR(INDEX(Barang!$A$2:$A$10001, MATCH(N17, Barang!$B$2:$B$10001, 0)), "Tidak ditemukan"))} | O17: {=IF(N17="","", IFERROR(INDEX(Barang!$C$2:$C$10001, MATCH(N17, Barang!$B$2:$B$10001, 0)), ""))} | P17: {=IF(N17="","", IFERROR(INDEX(Barang!$E$2:$E$10001, MATCH(N17, Barang!$B$2:$B$10001, 0)), ""))} | R17: {=IF(N17="","", IFERROR(INDEX(Barang!$F$2:$F$10001, MATCH(N17, Barang!$B$2:$B$10001, 0)) * Q17, ""))} | U17: - | V17: -
B18: {=IF(C18="","", IFERROR(INDEX(Barang!$A$2:$A$10001, MATCH(C18, Barang!$B$2:$B$10001, 0)), "Tidak ditemukan"))} -> KB001 | C18: Kuah Bakso | D18: {=IF(C18="","", IFERROR(INDEX(Barang!$C$2:$C$10001, MATCH(C18, Barang!$B$2:$B$10001, 0)), ""))} -> Bumbu | E18: {=IF(C18="","", IFERROR(INDEX(Barang!$E$2:$E$10001, MATCH(C18, Barang!$B$2:$B$10001, 0)), ""))} -> pcs | F18: 10 | G18: {=IF(C18="","", IFERROR(INDEX(Barang!$F$2:$F$10001, MATCH(C18, Barang!$B$2:$B$10001, 0)) * F18, ""))} -> 5000 | M18: {=IF(N18="","", IFERROR(INDEX(Barang!$A$2:$A$10001, MATCH(N18, Barang!$B$2:$B$10001, 0)), "Tidak ditemukan"))} | O18: {=IF(N18="","", IFERROR(INDEX(Barang!$C$2:$C$10001, MATCH(N18, Barang!$B$2:$B$10001, 0)), ""))} | P18: {=IF(N18="","", IFERROR(INDEX(Barang!$E$2:$E$10001, MATCH(N18, Barang!$B$2:$B$10001, 0)), ""))} | R18: {=IF(N18="","", IFERROR(INDEX(Barang!$F$2:$F$10001, MATCH(N18, Barang!$B$2:$B$10001, 0)) * Q18, ""))} | U18: - | V18: -
B19: {=IF(C19="","", IFERROR(INDEX(Barang!$A$2:$A$10001, MATCH(C19, Barang!$B$2:$B$10001, 0)), "Tidak ditemukan"))} -> TLR2 | C19: Telur 1/2 | D19: {=IF(C19="","", IFERROR(INDEX(Barang!$C$2:$C$10001, MATCH(C19, Barang!$B$2:$B$10001, 0)), ""))} -> Sembako | E19: {=IF(C19="","", IFERROR(INDEX(Barang!$E$2:$E$10001, MATCH(C19, Barang!$B$2:$B$10001, 0)), ""))} -> kg | F19: 10 | G19: {=IF(C19="","", IFERROR(INDEX(Barang!$F$2:$F$10001, MATCH(C19, Barang!$B$2:$B$10001, 0)) * F19, ""))} -> 155000 | I19: =SUM(G17:G19) -> 185000 | M19: {=IF(N19="","", IFERROR(INDEX(Barang!$A$2:$A$10001, MATCH(N19, Barang!$B$2:$B$10001, 0)), "Tidak ditemukan"))} | O19: {=IF(N19="","", IFERROR(INDEX(Barang!$C$2:$C$10001, MATCH(N19, Barang!$B$2:$B$10001, 0)), ""))} | P19: {=IF(N19="","", IFERROR(INDEX(Barang!$E$2:$E$10001, MATCH(N19, Barang!$B$2:$B$10001, 0)), ""))} | R19: {=IF(N19="","", IFERROR(INDEX(Barang!$F$2:$F$10001, MATCH(N19, Barang!$B$2:$B$10001, 0)) * Q19, ""))} | U19: - | V19: -
A20: 45942 | B20: {=IF(C20="","", IFERROR(INDEX(Barang!$A$2:$A$10001, MATCH(C20, Barang!$B$2:$B$10001, 0)), "Tidak ditemukan"))} -> RTP001 | C20: Roti Pia | D20: {=IF(C20="","", IFERROR(INDEX(Barang!$C$2:$C$10001, MATCH(C20, Barang!$B$2:$B$10001, 0)), ""))} -> Makanan | E20: {=IF(C20="","", IFERROR(INDEX(Barang!$E$2:$E$10001, MATCH(C20, Barang!$B$2:$B$10001, 0)), ""))} -> pcs | F20: 20 | G20: {=IF(C20="","", IFERROR(INDEX(Barang!$F$2:$F$10001, MATCH(C20, Barang!$B$2:$B$10001, 0)) * F20, ""))} -> 40000 | M20: {=IF(N20="","", IFERROR(INDEX(Barang!$A$2:$A$10001, MATCH(N20, Barang!$B$2:$B$10001, 0)), "Tidak ditemukan"))} | O20: {=IF(N20="","", IFERROR(INDEX(Barang!$C$2:$C$10001, MATCH(N20, Barang!$B$2:$B$10001, 0)), ""))} | P20: {=IF(N20="","", IFERROR(INDEX(Barang!$E$2:$E$10001, MATCH(N20, Barang!$B$2:$B$10001, 0)), ""))} | R20: {=IF(N20="","", IFERROR(INDEX(Barang!$F$2:$F$10001, MATCH(N20, Barang!$B$2:$B$10001, 0)) * Q20, ""))} | U20: - | V20: -
B21: {=IF(C21="","", IFERROR(INDEX(Barang!$A$2:$A$10001, MATCH(C21, Barang!$B$2:$B$10001, 0)), "Tidak ditemukan"))} -> KB001 | C21: Kuah Bakso | D21: {=IF(C21="","", IFERROR(INDEX(Barang!$C$2:$C$10001, MATCH(C21, Barang!$B$2:$B$10001, 0)), ""))} -> Bumbu | E21: {=IF(C21="","", IFERROR(INDEX(Barang!$E$2:$E$10001, MATCH(C21, Barang!$B$2:$B$10001, 0)), ""))} -> pcs | F21: 10 | G21: {=IF(C21="","", IFERROR(INDEX(Barang!$F$2:$F$10001, MATCH(C21, Barang!$B$2:$B$10001, 0)) * F21, ""))} -> 5000 | M21: {=IF(N21="","", IFERROR(INDEX(Barang!$A$2:$A$10001, MATCH(N21, Barang!$B$2:$B$10001, 0)), "Tidak ditemukan"))} | O21: {=IF(N21="","", IFERROR(INDEX(Barang!$C$2:$C$10001, MATCH(N21, Barang!$B$2:$B$10001, 0)), ""))} | P21: {=IF(N21="","", IFERROR(INDEX(Barang!$E$2:$E$10001, MATCH(N21, Barang!$B$2:$B$10001, 0)), ""))} | R21: {=IF(N21="","", IFERROR(INDEX(Barang!$F$2:$F$10001, MATCH(N21, Barang!$B$2:$B$10001, 0)) * Q21, ""))} | U21: - | V21: -
B22: {=IF(C22="","", IFERROR(INDEX(Barang!$A$2:$A$10001, MATCH(C22, Barang!$B$2:$B$10001, 0)), "Tidak ditemukan"))} -> DLC001 | C22: Dilan Cookies | D22: {=IF(C22="","", IFERROR(INDEX(Barang!$C$2:$C$10001, MATCH(C22, Barang!$B$2:$B$10001, 0)), ""))} -> Makanan | E22: {=IF(C22="","", IFERROR(INDEX(Barang!$E$2:$E$10001, MATCH(C22, Barang!$B$2:$B$10001, 0)), ""))} -> pcs | F22: 24 | G22: {=IF(C22="","", IFERROR(INDEX(Barang!$F$2:$F$10001, MATCH(C22, Barang!$B$2:$B$10001, 0)) * F22, ""))} -> 24000 | M22: {=IF(N22="","", IFERROR(INDEX(Barang!$A$2:$A$10001, MATCH(N22, Barang!$B$2:$B$10001, 0)), "Tidak ditemukan"))} | O22: {=IF(N22="","", IFERROR(INDEX(Barang!$C$2:$C$10001, MATCH(N22, Barang!$B$2:$B$10001, 0)), ""))} | P22: {=IF(N22="","", IFERROR(INDEX(Barang!$E$2:$E$10001, MATCH(N22, Barang!$B$2:$B$10001, 0)), ""))} | R22: {=IF(N22="","", IFERROR(INDEX(Barang!$F$2:$F$10001, MATCH(N22, Barang!$B$2:$B$10001, 0)) * Q22, ""))} | U22: - | V22: -
B23: {=IF(C23="","", IFERROR(INDEX(Barang!$A$2:$A$10001, MATCH(C23, Barang!$B$2:$B$10001, 0)), "Tidak ditemukan"))} -> GRR001 | C23: Goriorio | D23: {=IF(C23="","", IFERROR(INDEX(Barang!$C$2:$C$10001, MATCH(C23, Barang!$B$2:$B$10001, 0)), ""))} -> Makanan | E23: {=IF(C23="","", IFERROR(INDEX(Barang!$E$2:$E$10001, MATCH(C23, Barang!$B$2:$B$10001, 0)), ""))} -> pcs | F23: 24 | G23: {=IF(C23="","", IFERROR(INDEX(Barang!$F$2:$F$10001, MATCH(C23, Barang!$B$2:$B$10001, 0)) * F23, ""))} -> 12000 | I23: =SUM(G20:G23) -> 81000 | M23: {=IF(N23="","", IFERROR(INDEX(Barang!$A$2:$A$10001, MATCH(N23, Barang!$B$2:$B$10001, 0)), "Tidak ditemukan"))} | O23: {=IF(N23="","", IFERROR(INDEX(Barang!$C$2:$C$10001, MATCH(N23, Barang!$B$2:$B$10001, 0)), ""))} | P23: {=IF(N23="","", IFERROR(INDEX(Barang!$E$2:$E$10001, MATCH(N23, Barang!$B$2:$B$10001, 0)), ""))} | R23: {=IF(N23="","", IFERROR(INDEX(Barang!$F$2:$F$10001, MATCH(N23, Barang!$B$2:$B$10001, 0)) * Q23, ""))} | U23: - | V23: -
A24: 45943 | B24: {=IF(C24="","", IFERROR(INDEX(Barang!$A$2:$A$10001, MATCH(C24, Barang!$B$2:$B$10001, 0)), "Tidak ditemukan"))} -> GL1001 | C24: Gula 1kg | D24: {=IF(C24="","", IFERROR(INDEX(Barang!$C$2:$C$10001, MATCH(C24, Barang!$B$2:$B$10001, 0)), ""))} -> Sembako | E24: {=IF(C24="","", IFERROR(INDEX(Barang!$E$2:$E$10001, MATCH(C24, Barang!$B$2:$B$10001, 0)), ""))} -> kg | F24: 50 | G24: {=IF(C24="","", IFERROR(INDEX(Barang!$F$2:$F$10001, MATCH(C24, Barang!$B$2:$B$10001, 0)) * F24, ""))} -> 825000 | M24: {=IF(N24="","", IFERROR(INDEX(Barang!$A$2:$A$10001, MATCH(N24, Barang!$B$2:$B$10001, 0)), "Tidak ditemukan"))} | O24: {=IF(N24="","", IFERROR(INDEX(Barang!$C$2:$C$10001, MATCH(N24, Barang!$B$2:$B$10001, 0)), ""))} | P24: {=IF(N24="","", IFERROR(INDEX(Barang!$E$2:$E$10001, MATCH(N24, Barang!$B$2:$B$10001, 0)), ""))} | R24: {=IF(N24="","", IFERROR(INDEX(Barang!$F$2:$F$10001, MATCH(N24, Barang!$B$2:$B$10001, 0)) * Q24, ""))} | U24: - | V24: -
B25: {=IF(C25="","", IFERROR(INDEX(Barang!$A$2:$A$10001, MATCH(C25, Barang!$B$2:$B$10001, 0)), "Tidak ditemukan"))} -> TLR2 | C25: Telur 1/2 | D25: {=IF(C25="","", IFERROR(INDEX(Barang!$C$2:$C$10001, MATCH(C25, Barang!$B$2:$B$10001, 0)), ""))} -> Sembako | E25: {=IF(C25="","", IFERROR(INDEX(Barang!$E$2:$E$10001, MATCH(C25, Barang!$B$2:$B$10001, 0)), ""))} -> kg | F25: 10 | G25: {=IF(C25="","", IFERROR(INDEX(Barang!$F$2:$F$10001, MATCH(C25, Barang!$B$2:$B$10001, 0)) * F25, ""))} -> 155000 | M25: {=IF(N25="","", IFERROR(INDEX(Barang!$A$2:$A$10001, MATCH(N25, Barang!$B$2:$B$10001, 0)), "Tidak ditemukan"))} | O25: {=IF(N25="","", IFERROR(INDEX(Barang!$C$2:$C$10001, MATCH(N25, Barang!$B$2:$B$10001, 0)), ""))} | P25: {=IF(N25="","", IFERROR(INDEX(Barang!$E$2:$E$10001, MATCH(N25, Barang!$B$2:$B$10001, 0)), ""))} | R25: {=IF(N25="","", IFERROR(INDEX(Barang!$F$2:$F$10001, MATCH(N25, Barang!$B$2:$B$10001, 0)) * Q25, ""))} | U25: - | V25: -
B26: {=IF(C26="","", IFERROR(INDEX(Barang!$A$2:$A$10001, MATCH(C26, Barang!$B$2:$B$10001, 0)), "Tidak ditemukan"))} -> THD001 | C26: Teh Dandang | D26: {=IF(C26="","", IFERROR(INDEX(Barang!$C$2:$C$10001, MATCH(C26, Barang!$B$2:$B$10001, 0)), ""))} -> Minuman | E26: {=IF(C26="","", IFERROR(INDEX(Barang!$E$2:$E$10001, MATCH(C26, Barang!$B$2:$B$10001, 0)), ""))} -> pcs | F26: 12 | G26: {=IF(C26="","", IFERROR(INDEX(Barang!$F$2:$F$10001, MATCH(C26, Barang!$B$2:$B$10001, 0)) * F26, ""))} -> 24000 | M26: {=IF(N26="","", IFERROR(INDEX(Barang!$A$2:$A$10001, MATCH(N26, Barang!$B$2:$B$10001, 0)), "Tidak ditemukan"))} | O26: {=IF(N26="","", IFERROR(INDEX(Barang!$C$2:$C$10001, MATCH(N26, Barang!$B$2:$B$10001, 0)), ""))} | P26: {=IF(N26="","", IFERROR(INDEX(Barang!$E$2:$E$10001, MATCH(N26, Barang!$B$2:$B$10001, 0)), ""))} | R26: {=IF(N26="","", IFERROR(INDEX(Barang!$F$2:$F$10001, MATCH(N26, Barang!$B$2:$B$10001, 0)) * Q26, ""))} | U26: - | V26: -
B27: {=IF(C27="","", IFERROR(INDEX(Barang!$A$2:$A$10001, MATCH(C27, Barang!$B$2:$B$10001, 0)), "Tidak ditemukan"))} -> KPH001 | C27: Kopi hitam | D27: {=IF(C27="","", IFERROR(INDEX(Barang!$C$2:$C$10001, MATCH(C27, Barang!$B$2:$B$10001, 0)), ""))} -> Minuman | E27: {=IF(C27="","", IFERROR(INDEX(Barang!$E$2:$E$10001, MATCH(C27, Barang!$B$2:$B$10001, 0)), ""))} -> pcs | F27: 24 | G27: {=IF(C27="","", IFERROR(INDEX(Barang!$F$2:$F$10001, MATCH(C27, Barang!$B$2:$B$10001, 0)) * F27, ""))} -> 24000 | M27: {=IF(N27="","", IFERROR(INDEX(Barang!$A$2:$A$10001, MATCH(N27, Barang!$B$2:$B$10001, 0)), "Tidak ditemukan"))} | O27: {=IF(N27="","", IFERROR(INDEX(Barang!$C$2:$C$10001, MATCH(N27, Barang!$B$2:$B$10001, 0)), ""))} | P27: {=IF(N27="","", IFERROR(INDEX(Barang!$E$2:$E$10001, MATCH(N27, Barang!$B$2:$B$10001, 0)), ""))} | R27: {=IF(N27="","", IFERROR(INDEX(Barang!$F$2:$F$10001, MATCH(N27, Barang!$B$2:$B$10001, 0)) * Q27, ""))} | U27: - | V27: -
B28: {=IF(C28="","", IFERROR(INDEX(Barang!$A$2:$A$10001, MATCH(C28, Barang!$B$2:$B$10001, 0)), "Tidak ditemukan"))} -> RPK001 | C28: Rapika | D28: {=IF(C28="","", IFERROR(INDEX(Barang!$C$2:$C$10001, MATCH(C28, Barang!$B$2:$B$10001, 0)), ""))} -> Detergen | E28: {=IF(C28="","", IFERROR(INDEX(Barang!$E$2:$E$10001, MATCH(C28, Barang!$B$2:$B$10001, 0)), ""))} -> pcs | F28: 10 | G28: {=IF(C28="","", IFERROR(INDEX(Barang!$F$2:$F$10001, MATCH(C28, Barang!$B$2:$B$10001, 0)) * F28, ""))} -> 50000 | M28: {=IF(N28="","", IFERROR(INDEX(Barang!$A$2:$A$10001, MATCH(N28, Barang!$B$2:$B$10001, 0)), "Tidak ditemukan"))} | O28: {=IF(N28="","", IFERROR(INDEX(Barang!$C$2:$C$10001, MATCH(N28, Barang!$B$2:$B$10001, 0)), ""))} | P28: {=IF(N28="","", IFERROR(INDEX(Barang!$E$2:$E$10001, MATCH(N28, Barang!$B$2:$B$10001, 0)), ""))} | R28: {=IF(N28="","", IFERROR(INDEX(Barang!$F$2:$F$10001, MATCH(N28, Barang!$B$2:$B$10001, 0)) * Q28, ""))} | U28: - | V28: -
B29: {=IF(C29="","", IFERROR(INDEX(Barang!$A$2:$A$10001, MATCH(C29, Barang!$B$2:$B$10001, 0)), "Tidak ditemukan"))} -> MSK001 | C29: Masako | D29: {=IF(C29="","", IFERROR(INDEX(Barang!$C$2:$C$10001, MATCH(C29, Barang!$B$2:$B$10001, 0)), ""))} -> Bumbu | E29: {=IF(C29="","", IFERROR(INDEX(Barang!$E$2:$E$10001, MATCH(C29, Barang!$B$2:$B$10001, 0)), ""))} -> pcs | F29: 20 | G29: {=IF(C29="","", IFERROR(INDEX(Barang!$F$2:$F$10001, MATCH(C29, Barang!$B$2:$B$10001, 0)) * F29, ""))} -> 10000 | I29: =SUM(G24:G29) -> 1088000 | M29: {=IF(N29="","", IFERROR(INDEX(Barang!$A$2:$A$10001, MATCH(N29, Barang!$B$2:$B$10001, 0)), "Tidak ditemukan"))} | O29: {=IF(N29="","", IFERROR(INDEX(Barang!$C$2:$C$10001, MATCH(N29, Barang!$B$2:$B$10001, 0)), ""))} | P29: {=IF(N29="","", IFERROR(INDEX(Barang!$E$2:$E$10001, MATCH(N29, Barang!$B$2:$B$10001, 0)), ""))} | R29: {=IF(N29="","", IFERROR(INDEX(Barang!$F$2:$F$10001, MATCH(N29, Barang!$B$2:$B$10001, 0)) * Q29, ""))} | U29: - | V29: -
A30: 45944 | B30: {=IF(C30="","", IFERROR(INDEX(Barang!$A$2:$A$10001, MATCH(C30, Barang!$B$2:$B$10001, 0)), "Tidak ditemukan"))} -> MGR001 | C30: Mie Goreng | D30: {=IF(C30="","", IFERROR(INDEX(Barang!$C$2:$C$10001, MATCH(C30, Barang!$B$2:$B$10001, 0)), ""))} -> Makanan | E30: {=IF(C30="","", IFERROR(INDEX(Barang!$E$2:$E$10001, MATCH(C30, Barang!$B$2:$B$10001, 0)), ""))} -> pcs | F30: 40 | G30: {=IF(C30="","", IFERROR(INDEX(Barang!$F$2:$F$10001, MATCH(C30, Barang!$B$2:$B$10001, 0)) * F30, ""))} -> 140000 | M30: {=IF(N30="","", IFERROR(INDEX(Barang!$A$2:$A$10001, MATCH(N30, Barang!$B$2:$B$10001, 0)), "Tidak ditemukan"))} | O30: {=IF(N30="","", IFERROR(INDEX(Barang!$C$2:$C$10001, MATCH(N30, Barang!$B$2:$B$10001, 0)), ""))} | P30: {=IF(N30="","", IFERROR(INDEX(Barang!$E$2:$E$10001, MATCH(N30, Barang!$B$2:$B$10001, 0)), ""))} | R30: {=IF(N30="","", IFERROR(INDEX(Barang!$F$2:$F$10001, MATCH(N30, Barang!$B$2:$B$10001, 0)) * Q30, ""))} | U30: - | V30: -
B31: {=IF(C31="","", IFERROR(INDEX(Barang!$A$2:$A$10001, MATCH(C31, Barang!$B$2:$B$10001, 0)), "Tidak ditemukan"))} -> MKH001 | C31: Mie Kuah | D31: {=IF(C31="","", IFERROR(INDEX(Barang!$C$2:$C$10001, MATCH(C31, Barang!$B$2:$B$10001, 0)), ""))} -> Makanan | E31: {=IF(C31="","", IFERROR(INDEX(Barang!$E$2:$E$10001, MATCH(C31, Barang!$B$2:$B$10001, 0)), ""))} -> pcs | F31: 40 | G31: {=IF(C31="","", IFERROR(INDEX(Barang!$F$2:$F$10001, MATCH(C31, Barang!$B$2:$B$10001, 0)) * F31, ""))} -> 140000 | M31: {=IF(N31="","", IFERROR(INDEX(Barang!$A$2:$A$10001, MATCH(N31, Barang!$B$2:$B$10001, 0)), "Tidak ditemukan"))} | O31: {=IF(N31="","", IFERROR(INDEX(Barang!$C$2:$C$10001, MATCH(N31, Barang!$B$2:$B$10001, 0)), ""))} | P31: {=IF(N31="","", IFERROR(INDEX(Barang!$E$2:$E$10001, MATCH(N31, Barang!$B$2:$B$10001, 0)), ""))} | R31: {=IF(N31="","", IFERROR(INDEX(Barang!$F$2:$F$10001, MATCH(N31, Barang!$B$2:$B$10001, 0)) * Q31, ""))} | U31: - | V31: -
B32: {=IF(C32="","", IFERROR(INDEX(Barang!$A$2:$A$10001, MATCH(C32, Barang!$B$2:$B$10001, 0)), "Tidak ditemukan"))} -> KB001 | C32: Kuah Bakso | D32: {=IF(C32="","", IFERROR(INDEX(Barang!$C$2:$C$10001, MATCH(C32, Barang!$B$2:$B$10001, 0)), ""))} -> Bumbu | E32: {=IF(C32="","", IFERROR(INDEX(Barang!$E$2:$E$10001, MATCH(C32, Barang!$B$2:$B$10001, 0)), ""))} -> pcs | F32: 10 | G32: {=IF(C32="","", IFERROR(INDEX(Barang!$F$2:$F$10001, MATCH(C32, Barang!$B$2:$B$10001, 0)) * F32, ""))} -> 5000 | M32: {=IF(N32="","", IFERROR(INDEX(Barang!$A$2:$A$10001, MATCH(N32, Barang!$B$2:$B$10001, 0)), "Tidak ditemukan"))} | O32: {=IF(N32="","", IFERROR(INDEX(Barang!$C$2:$C$10001, MATCH(N32, Barang!$B$2:$B$10001, 0)), ""))} | P32: {=IF(N32="","", IFERROR(INDEX(Barang!$E$2:$E$10001, MATCH(N32, Barang!$B$2:$B$10001, 0)), ""))} | R32: {=IF(N32="","", IFERROR(INDEX(Barang!$F$2:$F$10001, MATCH(N32, Barang!$B$2:$B$10001, 0)) * Q32, ""))} | U32: - | V32: -
B33: {=IF(C33="","", IFERROR(INDEX(Barang!$A$2:$A$10001, MATCH(C33, Barang!$B$2:$B$10001, 0)), "Tidak ditemukan"))} -> TPL2 | C33: Tropical 2Lt | D33: {=IF(C33="","", IFERROR(INDEX(Barang!$C$2:$C$10001, MATCH(C33, Barang!$B$2:$B$10001, 0)), ""))} -> Minyak | E33: {=IF(C33="","", IFERROR(INDEX(Barang!$E$2:$E$10001, MATCH(C33, Barang!$B$2:$B$10001, 0)), ""))} -> Liter | F33: 20 | G33: {=IF(C33="","", IFERROR(INDEX(Barang!$F$2:$F$10001, MATCH(C33, Barang!$B$2:$B$10001, 0)) * F33, ""))} -> 800000 | M33: {=IF(N33="","", IFERROR(INDEX(Barang!$A$2:$A$10001, MATCH(N33, Barang!$B$2:$B$10001, 0)), "Tidak ditemukan"))} | O33: {=IF(N33="","", IFERROR(INDEX(Barang!$C$2:$C$10001, MATCH(N33, Barang!$B$2:$B$10001, 0)), ""))} | P33: {=IF(N33="","", IFERROR(INDEX(Barang!$E$2:$E$10001, MATCH(N33, Barang!$B$2:$B$10001, 0)), ""))} | R33: {=IF(N33="","", IFERROR(INDEX(Barang!$F$2:$F$10001, MATCH(N33, Barang!$B$2:$B$10001, 0)) * Q33, ""))} | U33: - | V33: -
B34: {=IF(C34="","", IFERROR(INDEX(Barang!$A$2:$A$10001, MATCH(C34, Barang!$B$2:$B$10001, 0)), "Tidak ditemukan"))} -> TLR2 | C34: Telur 1/2 | D34: {=IF(C34="","", IFERROR(INDEX(Barang!$C$2:$C$10001, MATCH(C34, Barang!$B$2:$B$10001, 0)), ""))} -> Sembako | E34: {=IF(C34="","", IFERROR(INDEX(Barang!$E$2:$E$10001, MATCH(C34, Barang!$B$2:$B$10001, 0)), ""))} -> kg | F34: 30 | G34: {=IF(C34="","", IFERROR(INDEX(Barang!$F$2:$F$10001, MATCH(C34, Barang!$B$2:$B$10001, 0)) * F34, ""))} -> 465000 | M34: {=IF(N34="","", IFERROR(INDEX(Barang!$A$2:$A$10001, MATCH(N34, Barang!$B$2:$B$10001, 0)), "Tidak ditemukan"))} | O34: {=IF(N34="","", IFERROR(INDEX(Barang!$C$2:$C$10001, MATCH(N34, Barang!$B$2:$B$10001, 0)), ""))} | P34: {=IF(N34="","", IFERROR(INDEX(Barang!$E$2:$E$10001, MATCH(N34, Barang!$B$2:$B$10001, 0)), ""))} | R34: {=IF(N34="","", IFERROR(INDEX(Barang!$F$2:$F$10001, MATCH(N34, Barang!$B$2:$B$10001, 0)) * Q34, ""))} | U34: - | V34: -
B35: {=IF(C35="","", IFERROR(INDEX(Barang!$A$2:$A$10001, MATCH(C35, Barang!$B$2:$B$10001, 0)), "Tidak ditemukan"))} -> MSK001 | C35: Masako | D35: {=IF(C35="","", IFERROR(INDEX(Barang!$C$2:$C$10001, MATCH(C35, Barang!$B$2:$B$10001, 0)), ""))} -> Bumbu | E35: {=IF(C35="","", IFERROR(INDEX(Barang!$E$2:$E$10001, MATCH(C35, Barang!$B$2:$B$10001, 0)), ""))} -> pcs | F35: 20 | G35: {=IF(C35="","", IFERROR(INDEX(Barang!$F$2:$F$10001, MATCH(C35, Barang!$B$2:$B$10001, 0)) * F35, ""))} -> 10000 | I35: =SUM(G30:G35) -> 1560000 | M35: {=IF(N35="","", IFERROR(INDEX(Barang!$A$2:$A$10001, MATCH(N35, Barang!$B$2:$B$10001, 0)), "Tidak ditemukan"))} | O35: {=IF(N35="","", IFERROR(INDEX(Barang!$C$2:$C$10001, MATCH(N35, Barang!$B$2:$B$10001, 0)), ""))} | P35: {=IF(N35="","", IFERROR(INDEX(Barang!$E$2:$E$10001, MATCH(N35, Barang!$B$2:$B$10001, 0)), ""))} | R35: {=IF(N35="","", IFERROR(INDEX(Barang!$F$2:$F$10001, MATCH(N35, Barang!$B$2:$B$10001, 0)) * Q35, ""))} | U35: - | V35: -
A36: 45945 | B36: {=IF(C36="","", IFERROR(INDEX(Barang!$A$2:$A$10001, MATCH(C36, Barang!$B$2:$B$10001, 0)), "Tidak ditemukan"))} -> MKH001 | C36: Mie Kuah | D36: {=IF(C36="","", IFERROR(INDEX(Barang!$C$2:$C$10001, MATCH(C36, Barang!$B$2:$B$10001, 0)), ""))} -> Makanan | E36: {=IF(C36="","", IFERROR(INDEX(Barang!$E$2:$E$10001, MATCH(C36, Barang!$B$2:$B$10001, 0)), ""))} -> pcs | F36: 40 | G36: {=IF(C36="","", IFERROR(INDEX(Barang!$F$2:$F$10001, MATCH(C36, Barang!$B$2:$B$10001, 0)) * F36, ""))} -> 140000 | M36: {=IF(N36="","", IFERROR(INDEX(Barang!$A$2:$A$10001, MATCH(N36, Barang!$B$2:$B$10001, 0)), "Tidak ditemukan"))} | O36: {=IF(N36="","", IFERROR(INDEX(Barang!$C$2:$C$10001, MATCH(N36, Barang!$B$2:$B$10001, 0)), ""))} | P36: {=IF(N36="","", IFERROR(INDEX(Barang!$E$2:$E$10001, MATCH(N36, Barang!$B$2:$B$10001, 0)), ""))} | R36: {=IF(N36="","", IFERROR(INDEX(Barang!$F$2:$F$10001, MATCH(N36, Barang!$B$2:$B$10001, 0)) * Q36, ""))} | U36: - | V36: -
