Workbook

Sheet Barang
A1: Kode Barang | B1: Nama Barang | C1: Kategori | D1: Supplier | E1: Satuan | F1: Harga
A2: SKB001 | B2: Soklin bubuk | C2: Detergen | E2: pcs | F2: 5000
A3: YP500 | B3: Yupi 500 | C3: Makanan | E3: pcs | F3: 500
A4: BPT1 | B4: B. putih 1/4 | C4: Rempah | E4: kg | F4: 8500
A5: TGP002 | B5: Tepung peyek | C5: Bumbu | E5: pcs | F5: 1000
A6: IDM002 | B6: Indomilk | C6: Minuman | D6: Sp | E6: pcs | F6: 1500
A7: CLB001 | B7: Chocolatos bubuk | C7: Minuman | E7: pcs | F7: 2500
A8: CL5001 | B8: Chocolatos 500 | C8: Makanan | E8: pcs | F8: 500
A9: LML002 | B9: Le mineral | C9: Minuman | E9: btl | F9: 19000
A10: GL1001 | B10: Gula 1kg | C10: Sembako | E10: kg | F10: 16500
A11: GRM01 | B11: Garam | C11: Bumbu | E11: pcs | F11: 2500
A12: PLS002 | B12: Pilus | C12: Makanan | E12: pcs | F12: 1000
A13: GSL002 | B13: Garuda slondok | C13: Makanan | E13: pcs | F13: 2000
A14: TSP001 | B14: Tisu Peony | C14: Tissue | E14: pcs | F14: 7000
A15: GSB002 | B15: Gery salut besar | C15: Makanan | E15: pcs | F15: 6500
A16: SCB002 | B16: Scoth brite | C16: Spon | E16: pcs | F16: 3500
A17: MBK002 | B17: Mie baked | C17: Makanan | E17: pcs | F17: 3000
A18: RTP001 | B18: Roti Pia | C18: Makanan | E18: pcs | F18: 2000
A19: RYC001 | B19: Royco | C19: Bumbu | D19: Sp | E19: pcs | F19: 500
A20: THD001 | B20: Teh Dandang | C20: Minuman | E20: pcs | F20: 2000
A21: RSB001 | B21: Rinso Bubuk | C21: Detergen | E21: pcs | F21: 5000
A22: PT1/4 | B22: Plastik 1/4 | C22: Plastik | E22: kg | F22: 2000
A23: PT1/2 | B23: Plastik 1/2 | C23: Plastik | E23: kg | F23: 3500
A24: PT1001 | B24: Plastik 1kg | C24: Plastik | E24: kg | F24: 5000
A25: KSK001 | B25: Kresek | C25: Plastik | E25: pack | F25: 4000
A26: GRA001 | B26: Garuda Atom | C26: Makanan | E26: pcs | F26: 2000
A27: DLN001 | B27: Dilan 1000 | C27: Makanan | E27: pcs | F27: 1000
A28: YP1001 | B28: Yupi 1000 | C28: Makanan | E28: pcs | F28: 1000
A29: LFB001 | B29: Lifebouy | C29: Sabun | E29: pcs | F29: 6000
A30: MGR001 | B30: Mie goreng | C30: Makanan | E30: pcs | F30: 3500
A31: MKH001 | B31: Mie kuah | C31: Makanan | E31: pcs | F31: 3500
... A67: PT001 | B67: Petis 1/4 | C67: Bumbu | E67: kg | F67: 25000
B68: Petis 1/2 | C68: Bumbu | E68: kg | F68: 50000
B69: Petis 1kg | C69: Bumbu | E69: kg | F69: 60000
A70: MSK001 | B70: Masako | C70: Bumbu | E70: pcs | F70: 500
A71: MKE001 | B71: Mie eko | C71: Makanan | E71: pcs | F71: 2500
A72: SNC001 | B72: Sunco 1L | C72: Minyak | E72: Liter | F72: 21000
A73: SNK001 | B73: Snack | C73: Makanan | E73: pcs | F73: 2000
A74: DLC001 | B74: Dilan cookies | C74: Makanan | E74: pcs | F74: 1000
A75: TLA001 | B75: Tolak angin | C75: Minuman | E75: pcs | F75: 5000
...

Sheet 2024
A1: Tanggal | B1: Kode Barang | C1: Nama Barang | D1: Kategori | E1: Satuan | F1: Jual | G1: Harga Jual | H1: Stok Awal | I1: Column 1 | J1: Tanggal | K1: Kode Barang | L1: Nama Barang | M1: Kategori | N1: Satuan | O1: Kulak | P1: Harga Jual | Q1: Harga Kulak | R1: Stok Akhir | S1: Minimal Stok | T1: Supplier
A2: 45292 | B2: BCB001 | C2: Boncabe | D2: Bumbu | E2: bungkus | F2: 2 | G2: 2000 | J2: 45292 | K2: BCB001 | L2: Boncabe | M2: Bumbu | N2: bungkus | O2: 12 | Q2: 20000 | R2: 10 | S2: - | T2: -
B3: MSK001 | C3: Masako | D3: Bumbu | E3: bungkus | F3: 2 | G3: 1000 | K3: MSK001 | L3: Masako | M3: Bumbu | N3: bungkus | O3: 36 | Q3: 14000 | R3: 58 | S3: - | T3: -
B4: IDM001 | C4: Indomilk | D4: Minuman | E4: bungkus | F4: 1 | G4: 2000 | K4: IDM001 | L4: Indomilk | M4: Minuman | N4: bungkus | O4: 70 | Q4: 77000 | R4: 59 | S4: - | T4: -
B5: NTS001 | C5: Nutrisari | D5: Minuman | E5: bungkus | F5: 3 | G5: 4500 | K5: NTS001 | L5: Nutrisari | M5: Minuman | N5: bungkus | O5: 60 | Q5: 75000 | R5: 57 | S5: - | T5: -
B6: DNY001 | C6: Downy | D6: Detergen | E6: bungkus | F6: 2 | G6: 1000 | K6: DN001 | L6: Downy | M6: Detergen | N6: bungkus | O6: 36 | Q6: 15000 | R6: 82 | S6: - | T6: -
B7: CLS001 | C7: Chocolatos | D7: Makanan | E7: bungkus | F7: 2 | G7: 2000 | K7: CCS001 | L7: Chocolatos | M7: Makanan | N7: bungkus | O7: 192 | Q7: 304000 | R7: 190 | S7: - | T7: -
B8: MCN001 | C8: Micin | D8: Bumbu | E8: bungkus | F8: 1 | G8: 1000 | K8: MCN001 | L8: Micin | M8: Bumbu | N8: bungkus | O8: 20 | Q8: 18500 | R8: 19 | S8: - | T8: -
B9: GDY001 | C9: GoodDay | D9: Minuman | E9: bungkus | F9: 1 | G9: 2000 | K9: GDY001 | L9: GoodDay | M9: Minuman | N9: bungkus | O9: 40 | Q9: 72000 | R9: 39 | S9: - | T9: -
B10: TLR001 | C10: Telur | D10: Sembako | E10: kilo | F10: 1 | G10: 27000 | K10: TLR001 | L10: Telur | M10: Sembako | N10: kilo | O10: 10 | Q10: 285000 | R10: 9 | S10: - | T10: -
A11: 45293 | B11: UBM001 | C11: Biskuit UBM | D11: Makanan | E11: bungkus | F11: 1 | G11: 10000 | J11: 45293 | K11: UBM001 | L11: Mari UBM | M11: Makanan | N11: bungkus | R11: -1 | S11: - | T11: -
B12: TGO001 | C12: Tanggo | D12: Makanan | E12: bungkus | F12: 1 | G12: 2000 | K12: TGO001 | L12: Tanggo | M12: Makanan | N12: bungkus | R12: -1 | S12: - | T12: -
B13: CCS001 | C13: Chocolatos | D13: Makanan | E13: bungkus | F13: 1 | G13: 1000 | K13: CCS001 | L13: Chocolatos | M13: Makanan | N13: bungkus | O13: 120 | Q13: 60000 | R13: 119 | S13: - | T13: -
B14: GRM001 | C14: Garam | D14: Bumbu | E14: bungkus | F14: 1 | G14: 2500 | K14: GRM001 | L14: Garam | M14: Bumbu | N14: bungkus | O14: 40 | Q14: 67000 | R14: 39 | S14: - | T14: -
B15: RYC001 | C15: Royco | D15: Bumbu | E15: bungkus | F15: 4 | G15: 2000 | K15: RYC001 | L15: Royco | M15: Bumbu | N15: bungkus | O15: 36 | Q15: 14500 | R15: -4 | S15: - | T15: -
B16: KP001 | C16: Kopi | D16: Minuman | E16: bungkus | F16: 10 | G16: 5500 | K16: KP001 | L16: Kopi k.a | M16: Minuman | N16: bungkus | R16: -10 | S16: - | T16: -
B17: MKH001 | C17: Mie kuah | D17: Makanan | E17: bungkus | F17: 1 | G17: 3000 | K17: MKH001 | L17: Mie kuah | M17: Makanan | N17: bungkus | O17: 20 | Q17: 53000 | R17: 19 | S17: - | T17: -
B18: CLB001 | C18: Chocolatos bubuk | D18: Minuman | E18: bungkus | F18: 1 | G18: 2000 | K18: CCSB001 | L18: Chocolatos bubuk | M18: Minuman | N18: bungkus | O18: 20 | Q18: 35000 | R18: 19 | S18: - | T18: -
B19: GL001 | C19: Gula | D19: Sembako | E19: kilo | F19: 1 | G19: 16000 | K19: GL001 | L19: Gula | M19: Sembako | N19: kilo | O19: 10 | Q19: 125000 | R19: 9 | S19: - | T19: -
B20: NTS001 | C20: Nutrisari | D20: Minuman | E20: bungkus | F20: 3 | G20: 4500 | K20: NTS001 | L20: Nutrisari | M20: Minuman | N20: bungkus | O20: 70 | Q20: 84000 | R20: -3 | S20: - | T20: -
B21: STN001 | C21: Santan | D21: Bumbu | E21: bungkus | F21: 1 | G21: 3000 | K21: STN001 | L21: Santan | M21: Bumbu | N21: bungkus | R21: -1 | S21: - | T21: -
B22: TLR001 | C22: Telur | D22: Sembako | E22: kilo | F22: 45689 | G22: 14000 | K22: TLR001 | L22: Telur | M22: Sembako | N22: kilo | O22: 10 | Q22: 282000 | R22: 26/11 | S22: - | T22: -
B23: GDY001 | C23: GoodDay | D23: Minuman | E23: bungkus | F23: 1 | G23: 2000 | K23: GDY001 | L23: GoodDay | M23: Minuman | N23: bungkus | O23: 20 | Q23: 42000 | R23: 19 | S23: - | T23: -
B24: PLS001 | C24: Pilus garuda | D24: Makanan | E24: bungkus | F24: 4 | G24: 4000 | K24: PLS001 | L24: Pilus garuda | M24: Makanan | N24: bungkus | O24: 20 | Q24: 16000 | R24: -4 | S24: - | T24: -
B25: PYP001 | C25: Permen Yupi | D25: Makanan | E25: bungkus | F25: 2 | G25: 2000 | K25: PYP001 | L25: Permen Yupi | M25: Makanan | N25: bungkus | O25: 288 | Q25: 120000 | R25: 286 | S25: - | T25: -
A26: 45294 | B26: RCK001 | C26: Racik | D26: Bumbu | E26: bungkus | F26: 1 | G26: 2000 | J26: 45294 | K26: RCK001 | L26: Racik | M26: Bumbu | N26: bungkus | O26: 20 | Q26: 33000 | R26: 19 | S26: - | T26: -
B27: KRS001 | C27: Kara Santan | D27: Bumbu | E27: bungkus | F27: 1 | G27: 3500 | K27: KRS001 | L27: Kara Santan | M27: Bumbu | N27: bungkus | O27: 15 | Q27: 86500 | R27: 14 | S27: - | T27: -
B28: MSK001 | C28: Masako | D28: Bumbu | E28: bungkus | F28: 1 | G28: 500 | K28: MSK001 | L28: Masako | M28: Bumbu | N28: bungkus | O28: 72 | Q28: 27000 | R28: 71 | S28: - | T28: -
B29: LDB001 | C29: Lada Bubuk | D29: Bumbu | E29: bungkus | F29: 1 | G29: 1000 | K29: LDB001 | L29: Lada Bubuk | M29: Bumbu | N29: bungkus | R29: -1 | S29: - | T29: -
B30: BPT001 | C30: Bawang Putih | D30: Bumbu | E30: kilo | F30: 45748 | G30: 8500 | K30: BPT001 | L30: Bawang Putih | M30: Rempah | N30: kilo | O30: 2 | Q30: 76000 | R30: 30/9 | S30: - | T30: -
B31: PYP001 | C31: Permen Yupi | D31: Makanan | E31: bungkus | F31: 8 | G31: 4000 | K31: PYP001 | L31: Permen Yupi | M31: Makanan | N31: bungkus | O31: 288 | Q31: 120000 | R31: 280 | S31: - | T31: -
B32: MGR001 | C32: Mie Goreng | D32: Makanan | E32: bungkus | F32: 2 | G32: 7000 | K32: MGR001 | L32: Mie Goreng | M32: Makanan | N32: bungkus | O32: 20 | Q32: 56000 | R32: 18 | S32: - | T32: -
B33: MPD001 | C33: Mie Panda | D33: Makanan | E33: bungkus | F33: 1 | G33: 5000 | K33: MPD001 | L33: Mie Panda | M33: Makanan | N33: bungkus | R33: -1 | S33: - | T33: -
B34: TPG001 | C34: Tepung Geprek | D34: Bumbu mix | E34: bungkus | F34: 1 | G34: 11000 | K34: TPG001 | L34: Tepung Geprek | M34: Bumbu mix | N34: bungkus | R34: -1 | S34: - | T34: -
B35: TPJ001 | C35: Tepung Jempol | D35: Bumbu mix | E35: bungkus | F35: 1 | G35: 3000 | K35: TPJ001 | L35: Tepung Jempol | M35: Bumbu mix | N35: bungkus | O35: 10 | Q35: 22000 | R35: 9 | S35: - | T35: -
B36: SDB001 | C36: Sedaap Bumbu | D36: Bumbu | E36: bungkus | F36: 3 | G36: 3000 | K36: SDPB001 | L36: Sedaap Bumbu | M36: Bumbu | N36: bungkus | O36: 192 | Q36: 304000 | R36: 189 | S36: - | T36: -
B37: CLS001 | C37: Chocolatos | D37: Makanan | E37: bungkus | F37: 2 | G37: 2000 | K37: CCS001 | L37: Chocolatos | M37: Makanan | N37: bungkus | O37: 96 | Q37: 105000 | R37: 94 | S37: - | T37: -
B38: PLS001 | C38: Pilus garuda | D38: Makanan | E38: bungkus | F38: 1 | G38: 1000 | K38: PLS001 | L38: Pilus garuda | M38: Makanan | N38: bungkus | R38: -1 | S38: - | T38: -
B39: LMR001 | C39: Le mineral | D39: Minuman | E39: botol | F39: 1 | G39: 19000 | K39: LMR001 | L39: Le mineral | M39: Minuman | N39: botol | R39: -1 | S39: - | T39: -
B40: DTL001 | C40: Detol | D40: Sabun | E40: bungkus | F40: 1 | G40: 6000 | K40: DTL001 | L40: Detol | M40: Sabun | N40: bungkus | O40: 5 | Q40: 31500 | R40: 4 | S40: - | T40: -
...

Sheet 2025
A1: Tanggal | B1: Kode Barang | C1: Nama Barang | D1: Kategori | E1: Satuan | F1: Jual | G1: Harga Jual | H1: Stok Awal | J1: Tanggal | K1: Kode Barang | L1: Nama Barang | M1: Kategori | N1: Satuan | O1: Kulak | P1: Harga Jual | Q1: Harga Kulak | R1: Stok Akhir | S1: Minimal Stok | T1: Supplier
A2: 45938 | B2: ADS001 | C2: Adem Sari | D2: Minuman | E2: pcs | F2: 1 | G2: 2500 | K2: {=IF(L2="","", IFERROR(INDEX(Barang!$A$2:$A$10001, MATCH(L2, Barang!$B$2:$B$10001, 0)), "Tidak ditemukan"))} | M2: {=IF(L2="","", IFERROR(INDEX(Barang!$C$2:$C$10001, MATCH(L2, Barang!$B$2:$B$10001, 0)), ""))} | N2: {=IF(L2="","", IFERROR(INDEX(Barang!$E$2:$E$10001, MATCH(L2, Barang!$B$2:$B$10001, 0)), ""))} | P2: {=IF(L2="","", IFERROR(INDEX(Barang!$F$2:$F$10001, MATCH(L2, Barang!$B$2:$B$10001, 0)) * O2, ""))} | S2: - | T2: -
B3: {=IF(C3="","", IFERROR(INDEX(Barang!$A$2:$A$10001, MATCH(C3, Barang!$B$2:$B$10001, 0)), "Tidak ditemukan"))} -> TPL2 | C3: Tropical 2Lt | D3: {=IF(C3="","", IFERROR(INDEX(Barang!$C$2:$C$10001, MATCH(C3, Barang!$B$2:$B$10001, 0)), ""))} -> Minyak | E3: {=IF(C3="","", IFERROR(INDEX(Barang!$E$2:$E$10001, MATCH(C3, Barang!$B$2:$B$10001, 0)), ""))} -> Liter | F3: 1 | G3: {=IF(C3="","", IFERROR(INDEX(Barang!$F$2:$F$10001, MATCH(C3, Barang!$B$2:$B$10001, 0)) * F3, ""))} -> 40000 | K3: {=IF(L3="","", IFERROR(INDEX(Barang!$A$2:$A$10001, MATCH(L3, Barang!$B$2:$B$10001, 0)), "Tidak ditemukan"))} | M3: {=IF(L3="","", IFERROR(INDEX(Barang!$C$2:$C$10001, MATCH(L3, Barang!$B$2:$B$10001, 0)), ""))} | N3: {=IF(L3="","", IFERROR(INDEX(Barang!$E$2:$E$10001, MATCH(L3, Barang!$B$2:$B$10001, 0)), ""))} | P3: {=IF(L3="","", IFERROR(INDEX(Barang!$F$2:$F$10001, MATCH(L3, Barang!$B$2:$B$10001, 0)) * O3, ""))} | S3: - | T3: -
B4: {=IF(C4="","", IFERROR(INDEX(Barang!$A$2:$A$10001, MATCH(C4, Barang!$B$2:$B$10001, 0)), "Tidak ditemukan"))} -> LFB001 | C4: Lifebouy | D4: {=IF(C4="","", IFERROR(INDEX(Barang!$C$2:$C$10001, MATCH(C4, Barang!$B$2:$B$10001, 0)), ""))} -> Sabun | E4: {=IF(C4="","", IFERROR(INDEX(Barang!$E$2:$E$10001, MATCH(C4, Barang!$B$2:$B$10001, 0)), ""))} -> pcs | F4: 1 | G4: {=IF(C4="","", IFERROR(INDEX(Barang!$F$2:$F$10001, MATCH(C4, Barang!$B$2:$B$10001, 0)) * F4, ""))} -> 6000 | K4: {=IF(L4="","", IFERROR(INDEX(Barang!$A$2:$A$10001, MATCH(L4, Barang!$B$2:$B$10001, 0)), "Tidak ditemukan"))} | M4: {=IF(L4="","", IFERROR(INDEX(Barang!$C$2:$C$10001, MATCH(L4, Barang!$B$2:$B$10001, 0)), ""))} | N4: {=IF(L4="","", IFERROR(INDEX(Barang!$E$2:$E$10001, MATCH(L4, Barang!$B$2:$B$10001, 0)), ""))} | P4: {=IF(L4="","", IFERROR(INDEX(Barang!$F$2:$F$10001, MATCH(L4, Barang!$B$2:$B$10001, 0)) * O4, ""))} | S4: - | T4: -
B5: {=IF(C5="","", IFERROR(INDEX(Barang!$A$2:$A$10001, MATCH(C5, Barang!$B$2:$B$10001, 0)), "Tidak ditemukan"))} -> TSP001 | C5: Tisu peony | D5: {=IF(C5="","", IFERROR(INDEX(Barang!$C$2:$C$10001, MATCH(C5, Barang!$B$2:$B$10001, 0)), ""))} -> Tissue | E5: {=IF(C5="","", IFERROR(INDEX(Barang!$E$2:$E$10001, MATCH(C5, Barang!$B$2:$B$10001, 0)), ""))} -> pcs | F5: 1 | G5: {=IF(C5="","", IFERROR(INDEX(Barang!$F$2:$F$10001, MATCH(C5, Barang!$B$2:$B$10001, 0)) * F5, ""))} -> 7000 | K5: {=IF(L5="","", IFERROR(INDEX(Barang!$A$2:$A$10001, MATCH(L5, Barang!$B$2:$B$10001, 0)), "Tidak ditemukan"))} | M5: {=IF(L5="","", IFERROR(INDEX(Barang!$C$2:$C$10001, MATCH(L5, Barang!$B$2:$B$10001, 0)), ""))} | N5: {=IF(L5="","", IFERROR(INDEX(Barang!$E$2:$E$10001, MATCH(L5, Barang!$B$2:$B$10001, 0)), ""))} | P5: {=IF(L5="","", IFERROR(INDEX(Barang!$F$2:$F$10001, MATCH(L5, Barang!$B$2:$B$10001, 0)) * O5, ""))} | S5: - | T5: -
B6: {=IF(C6="","", IFERROR(INDEX(Barang!$A$2:$A$10001, MATCH(C6, Barang!$B$2:$B$10001, 0)), "Tidak ditemukan"))} -> SAR001 | C6: Saori | D6: {=IF(C6="","", IFERROR(INDEX(Barang!$C$2:$C$10001, MATCH(C6, Barang!$B$2:$B$10001, 0)), ""))} -> Bumbu | E6: {=IF(C6="","", IFERROR(INDEX(Barang!$E$2:$E$10001, MATCH(C6, Barang!$B$2:$B$10001, 0)), ""))} -> pcs | F6: 1 | G6: {=IF(C6="","", IFERROR(INDEX(Barang!$F$2:$F$10001, MATCH(C6, Barang!$B$2:$B$10001, 0)) * F6, ""))} -> 3000 | K6: {=IF(L6="","", IFERROR(INDEX(Barang!$A$2:$A$10001, MATCH(L6, Barang!$B$2:$B$10001, 0)), "Tidak ditemukan"))} | M6: {=IF(L6="","", IFERROR(INDEX(Barang!$C$2:$C$10001, MATCH(L6, Barang!$B$2:$B$10001, 0)), ""))} | N6: {=IF(L6="","", IFERROR(INDEX(Barang!$E$2:$E$10001, MATCH(L6, Barang!$B$2:$B$10001, 0)), ""))} | P6: {=IF(L6="","", IFERROR(INDEX(Barang!$F$2:$F$10001, MATCH(L6, Barang!$B$2:$B$10001, 0)) * O6, ""))} | S6: - | T6: -
A7: 45939 | B7: {=IF(C7="","", IFERROR(INDEX(Barang!$A$2:$A$10001, MATCH(C7, Barang!$B$2:$B$10001, 0)), "Tidak ditemukan"))} -> TGJ001 | C7: Tepung Jempol | D7: Bumbu | E7: pcs | F7: 10 | G7: 30000 | K7: {=IF(L7="","", IFERROR(INDEX(Barang!$A$2:$A$10001, MATCH(L7, Barang!$B$2:$B$10001, 0)), "Tidak ditemukan"))} | M7: {=IF(L7="","", IFERROR(INDEX(Barang!$C$2:$C$10001, MATCH(L7, Barang!$B$2:$B$10001, 0)), ""))} | N7: {=IF(L7="","", IFERROR(INDEX(Barang!$E$2:$E$10001, MATCH(L7, Barang!$B$2:$B$10001, 0)), ""))} | P7: {=IF(L7="","", IFERROR(INDEX(Barang!$F$2:$F$10001, MATCH(L7, Barang!$B$2:$B$10001, 0)) * O7, ""))} | S7: - | T7: -
B8: {=IF(C8="","", IFERROR(INDEX(Barang!$A$2:$A$10001, MATCH(C8, Barang!$B$2:$B$10001, 0)), "Tidak ditemukan"))} -> MGR001 | C8: Mie Goreng | D8: Makanan | E8: pcs | F8: 40 | G8: 140000 | K8: {=IF(L8="","", IFERROR(INDEX(Barang!$A$2:$A$10001, MATCH(L8, Barang!$B$2:$B$10001, 0)), "Tidak ditemukan"))} | M8: {=IF(L8="","", IFERROR(INDEX(Barang!$C$2:$C$10001, MATCH(L8, Barang!$B$2:$B$10001, 0)), ""))} | N8: {=IF(L8="","", IFERROR(INDEX(Barang!$E$2:$E$10001, MATCH(L8, Barang!$B$2:$B$10001, 0)), ""))} | P8: {=IF(L8="","", IFERROR(INDEX(Barang!$F$2:$F$10001, MATCH(L8, Barang!$B$2:$B$10001, 0)) * O8, ""))} | S8: - | T8: -
B9: {=IF(C9="","", IFERROR(INDEX(Barang!$A$2:$A$10001, MATCH(C9, Barang!$B$2:$B$10001, 0)), "Tidak ditemukan"))} -> GL1001 | C9: Gula 1kg | D9: Bumbu | E9: kg | F9: 50 | G9: 825000 | K9: {=IF(L9="","", IFERROR(INDEX(Barang!$A$2:$A$10001, MATCH(L9, Barang!$B$2:$B$10001, 0)), "Tidak ditemukan"))} | M9: {=IF(L9="","", IFERROR(INDEX(Barang!$C$2:$C$10001, MATCH(L9, Barang!$B$2:$B$10001, 0)), ""))} | N9: {=IF(L9="","", IFERROR(INDEX(Barang!$E$2:$E$10001, MATCH(L9, Barang!$B$2:$B$10001, 0)), ""))} | P9: {=IF(L9="","", IFERROR(INDEX(Barang!$F$2:$F$10001, MATCH(L9, Barang!$B$2:$B$10001, 0)) * O9, ""))} | S9: - | T9: -
B10: {=IF(C10="","", IFERROR(INDEX(Barang!$A$2:$A$10001, MATCH(C10, Barang!$B$2:$B$10001, 0)), "Tidak ditemukan"))} -> RTP001 | C10: Roti Pia | D10: Makanan | E10: pcs | F10: 30 | G10: 60000 | K10: {=IF(L10="","", IFERROR(INDEX(Barang!$A$2:$A$10001, MATCH(L10, Barang!$B$2:$B$10001, 0)), "Tidak ditemukan"))} | M10: {=IF(L10="","", IFERROR(INDEX(Barang!$C$2:$C$10001, MATCH(L10, Barang!$B$2:$B$10001, 0)), ""))} | N10: {=IF(L10="","", IFERROR(INDEX(Barang!$E$2:$E$10001, MATCH(L10, Barang!$B$2:$B$10001, 0)), ""))} | P10: {=IF(L10="","", IFERROR(INDEX(Barang!$F$2:$F$10001, MATCH(L10, Barang!$B$2:$B$10001, 0)) * O10, ""))}
B11: {=IF(C11="","", IFERROR(INDEX(Barang!$A$2:$A$10001, MATCH(C11, Barang!$B$2:$B$10001, 0)), "Tidak ditemukan"))} -> SC001 | C11: Soklin Cair | D11: Sabun | E11: pcs | F11: 10 | G11: 90000 | K11: {=IF(L11="","", IFERROR(INDEX(Barang!$A$2:$A$10001, MATCH(L11, Barang!$B$2:$B$10001, 0)), "Tidak ditemukan"))} | M11: {=IF(L11="","", IFERROR(INDEX(Barang!$C$2:$C$10001, MATCH(L11, Barang!$B$2:$B$10001, 0)), ""))} | N11: {=IF(L11="","", IFERROR(INDEX(Barang!$E$2:$E$10001, MATCH(L11, Barang!$B$2:$B$10001, 0)), ""))} | P11: {=IF(L11="","", IFERROR(INDEX(Barang!$F$2:$F$10001, MATCH(L11, Barang!$B$2:$B$10001, 0)) * O11, ""))} | S11: - | T11: -
A12: 45940 | B12: {=IF(C12="","", IFERROR(INDEX(Barang!$A$2:$A$10001, MATCH(C12, Barang!$B$2:$B$10001, 0)), "Tidak ditemukan"))} -> BPT1 | C12: B. putih 1/4 | D12: Bumbu | E12: kg | F12: 20 | G12: 170000 | K12: {=IF(L12="","", IFERROR(INDEX(Barang!$A$2:$A$10001, MATCH(L12, Barang!$B$2:$B$10001, 0)), "Tidak ditemukan"))} | M12: {=IF(L12="","", IFERROR(INDEX(Barang!$C$2:$C$10001, MATCH(L12, Barang!$B$2:$B$10001, 0)), ""))} | N12: {=IF(L12="","", IFERROR(INDEX(Barang!$E$2:$E$10001, MATCH(L12, Barang!$B$2:$B$10001, 0)), ""))} | P12: {=IF(L12="","", IFERROR(INDEX(Barang!$F$2:$F$10001, MATCH(L12, Barang!$B$2:$B$10001, 0)) * O12, ""))} | S12: - | T12: -
B13: {=IF(C13="","", IFERROR(INDEX(Barang!$A$2:$A$10001, MATCH(C13, Barang!$B$2:$B$10001, 0)), "Tidak ditemukan"))} -> EKC001 | C13: Ekonomi Cair | D13: Sabun | E13: pcs | F13: 10 | G13: 90000 | K13: {=IF(L13="","", IFERROR(INDEX(Barang!$A$2:$A$10001, MATCH(L13, Barang!$B$2:$B$10001, 0)), "Tidak ditemukan"))} | M13: {=IF(L13="","", IFERROR(INDEX(Barang!$C$2:$C$10001, MATCH(L13, Barang!$B$2:$B$10001, 0)), ""))} | N13: {=IF(L13="","", IFERROR(INDEX(Barang!$E$2:$E$10001, MATCH(L13, Barang!$B$2:$B$10001, 0)), ""))} | P13: {=IF(L13="","", IFERROR(INDEX(Barang!$F$2:$F$10001, MATCH(L13, Barang!$B$2:$B$10001, 0)) * O13, ""))} | S13: - | T13: -
B14: {=IF(C14="","", IFERROR(INDEX(Barang!$A$2:$A$10001, MATCH(C14, Barang!$B$2:$B$10001, 0)), "Tidak ditemukan"))} -> STS | C14: Santan Sasa | D14: Bumbu | E14: pcs | F14: 10 | G14: 50000 | K14: {=IF(L14="","", IFERROR(INDEX(Barang!$A$2:$A$10001, MATCH(L14, Barang!$B$2:$B$10001, 0)), "Tidak ditemukan"))} | M14: {=IF(L14="","", IFERROR(INDEX(Barang!$C$2:$C$10001, MATCH(L14, Barang!$B$2:$B$10001, 0)), ""))} | N14: {=IF(L14="","", IFERROR(INDEX(Barang!$E$2:$E$10001, MATCH(L14, Barang!$B$2:$B$10001, 0)), ""))} | P14: {=IF(L14="","", IFERROR(INDEX(Barang!$F$2:$F$10001, MATCH(L14, Barang!$B$2:$B$10001, 0)) * O14, ""))} | S14: - | T14: -
B15: {=IF(C15="","", IFERROR(INDEX(Barang!$A$2:$A$10001, MATCH(C15, Barang!$B$2:$B$10001, 0)), "Tidak ditemukan"))} -> DSO001 | C15: Desaku Opor | D15: Bumbu | E15: pcs | F15: 10 | G15: 35000 | K15: {=IF(L15="","", IFERROR(INDEX(Barang!$A$2:$A$10001, MATCH(L15, Barang!$B$2:$B$10001, 0)), "Tidak ditemukan"))} | M15: {=IF(L15="","", IFERROR(INDEX(Barang!$C$2:$C$10001, MATCH(L15, Barang!$B$2:$B$10001, 0)), ""))} | N15: {=IF(L15="","", IFERROR(INDEX(Barang!$E$2:$E$10001, MATCH(L15, Barang!$B$2:$B$10001, 0)), ""))} | P15: {=IF(L15="","", IFERROR(INDEX(Barang!$F$2:$F$10001, MATCH(L15, Barang!$B$2:$B$10001, 0)) * O15, ""))} | S15: - | T15: -
B16: {=IF(C16="","", IFERROR(INDEX(Barang!$A$2:$A$10001, MATCH(C16, Barang!$B$2:$B$10001, 0)), "Tidak ditemukan"))} -> IDM002 | C16: Indomilk | D16: Minuman | E16: pcs | F16: 20 | G16: 180000 | K16: {=IF(L16="","", IFERROR(INDEX(Barang!$A$2:$A$10001, MATCH(L16, Barang!$B$2:$B$10001, 0)), "Tidak ditemukan"))} | M16: {=IF(L16="","", IFERROR(INDEX(Barang!$C$2:$C$10001, MATCH(L16, Barang!$B$2:$B$10001, 0)), ""))} | N16: {=IF(L16="","", IFERROR(INDEX(Barang!$E$2:$E$10001, MATCH(L16, Barang!$B$2:$B$10001, 0)), ""))} | P16: {=IF(L16="","", IFERROR(INDEX(Barang!$F$2:$F$10001, MATCH(L16, Barang!$B$2:$B$10001, 0)) * O16, ""))} | S16: - | T16: -
A17: 45941 | B17: {=IF(C17="","", IFERROR(INDEX(Barang!$A$2:$A$10001, MATCH(C17, Barang!$B$2:$B$10001, 0)), "Tidak ditemukan"))} -> MSK001 | C17: Masako | D17: Bumbu | E17: pcs | F17: 50 | G17: 20000 | K17: {=IF(L17="","", IFERROR(INDEX(Barang!$A$2:$A$10001, MATCH(L17, Barang!$B$2:$B$10001, 0)), "Tidak ditemukan"))} | M17: {=IF(L17="","", IFERROR(INDEX(Barang!$C$2:$C$10001, MATCH(L17, Barang!$B$2:$B$10001, 0)), ""))} | N17: {=IF(L17="","", IFERROR(INDEX(Barang!$E$2:$E$10001, MATCH(L17, Barang!$B$2:$B$10001, 0)), ""))} | P17: {=IF(L17="","", IFERROR(INDEX(Barang!$F$2:$F$10001, MATCH(L17, Barang!$B$2:$B$10001, 0)) * O17, ""))} | S17: - | T17: -
B18: {=IF(C18="","", IFERROR(INDEX(Barang!$A$2:$A$10001, MATCH(C18, Barang!$B$2:$B$10001, 0)), "Tidak ditemukan"))} -> KB001 | C18: Kuah Bakso | D18: Bumbu | E18: pcs | F18: 10 | G18: 5000 | K18: {=IF(L18="","", IFERROR(INDEX(Barang!$A$2:$A$10001, MATCH(L18, Barang!$B$2:$B$10001, 0)), "Tidak ditemukan"))} | M18: {=IF(L18="","", IFERROR(INDEX(Barang!$C$2:$C$10001, MATCH(L18, Barang!$B$2:$B$10001, 0)), ""))} | N18: {=IF(L18="","", IFERROR(INDEX(Barang!$E$2:$E$10001, MATCH(L18, Barang!$B$2:$B$10001, 0)), ""))} | P18: {=IF(L18="","", IFERROR(INDEX(Barang!$F$2:$F$10001, MATCH(L18, Barang!$B$2:$B$10001, 0)) * O18, ""))} | S18: - | T18: -
B19: {=IF(C19="","", IFERROR(INDEX(Barang!$A$2:$A$10001, MATCH(C19, Barang!$B$2:$B$10001, 0)), "Tidak ditemukan"))} -> TLR2 | C19: Telur 1/2 | D19: Makanan | E19: kg | F19: 10 | G19: 310000 | K19: {=IF(L19="","", IFERROR(INDEX(Barang!$A$2:$A$10001, MATCH(L19, Barang!$B$2:$B$10001, 0)), "Tidak ditemukan"))} | M19: {=IF(L19="","", IFERROR(INDEX(Barang!$C$2:$C$10001, MATCH(L19, Barang!$B$2:$B$10001, 0)), ""))} | N19: {=IF(L19="","", IFERROR(INDEX(Barang!$E$2:$E$10001, MATCH(L19, Barang!$B$2:$B$10001, 0)), ""))} | P19: {=IF(L19="","", IFERROR(INDEX(Barang!$F$2:$F$10001, MATCH(L19, Barang!$B$2:$B$10001, 0)) * O19, ""))} | S19: - | T19: -
A20: 45942 | B20: {=IF(C20="","", IFERROR(INDEX(Barang!$A$2:$A$10001, MATCH(C20, Barang!$B$2:$B$10001, 0)), "Tidak ditemukan"))} -> RTP001 | C20: Roti Pia | D20: Makanan | E20: pcs | F20: 20 | G20: 40000 | K20: {=IF(L20="","", IFERROR(INDEX(Barang!$A$2:$A$10001, MATCH(L20, Barang!$B$2:$B$10001, 0)), "Tidak ditemukan"))} | M20: {=IF(L20="","", IFERROR(INDEX(Barang!$C$2:$C$10001, MATCH(L20, Barang!$B$2:$B$10001, 0)), ""))} | N20: {=IF(L20="","", IFERROR(INDEX(Barang!$E$2:$E$10001, MATCH(L20, Barang!$B$2:$B$10001, 0)), ""))} | P20: {=IF(L20="","", IFERROR(INDEX(Barang!$F$2:$F$10001, MATCH(L20, Barang!$B$2:$B$10001, 0)) * O20, ""))} | S20: - | T20: -
B21: {=IF(C21="","", IFERROR(INDEX(Barang!$A$2:$A$10001, MATCH(C21, Barang!$B$2:$B$10001, 0)), "Tidak ditemukan"))} -> KB001 | C21: Kuah Bakso | D21: Bumbu | E21: pcs | F21: 10 | G21: 5000 | K21: {=IF(L21="","", IFERROR(INDEX(Barang!$A$2:$A$10001, MATCH(L21, Barang!$B$2:$B$10001, 0)), "Tidak ditemukan"))} | M21: {=IF(L21="","", IFERROR(INDEX(Barang!$C$2:$C$10001, MATCH(L21, Barang!$B$2:$B$10001, 0)), ""))} | N21: {=IF(L21="","", IFERROR(INDEX(Barang!$E$2:$E$10001, MATCH(L21, Barang!$B$2:$B$10001, 0)), ""))} | P21: {=IF(L21="","", IFERROR(INDEX(Barang!$F$2:$F$10001, MATCH(L21, Barang!$B$2:$B$10001, 0)) * O21, ""))} | S21: - | T21: -
B22: {=IF(C22="","", IFERROR(INDEX(Barang!$A$2:$A$10001, MATCH(C22, Barang!$B$2:$B$10001, 0)), "Tidak ditemukan"))} -> DLC001 | C22: Dilan Cookies | D22: Makanan | E22: pcs | F22: 24 | G22: 24000 | K22: {=IF(L22="","", IFERROR(INDEX(Barang!$A$2:$A$10001, MATCH(L22, Barang!$B$2:$B$10001, 0)), "Tidak ditemukan"))} | M22: {=IF(L22="","", IFERROR(INDEX(Barang!$C$2:$C$10001, MATCH(L22, Barang!$B$2:$B$10001, 0)), ""))} | N22: {=IF(L22="","", IFERROR(INDEX(Barang!$E$2:$E$10001, MATCH(L22, Barang!$B$2:$B$10001, 0)), ""))} | P22: {=IF(L22="","", IFERROR(INDEX(Barang!$F$2:$F$10001, MATCH(L22, Barang!$B$2:$B$10001, 0)) * O22, ""))} | S22: - | T22: -
B23: {=IF(C23="","", IFERROR(INDEX(Barang!$A$2:$A$10001, MATCH(C23, Barang!$B$2:$B$10001, 0)), "Tidak ditemukan"))} -> GRR001 | C23: Goriorio | D23: Makanan | E23: pcs | F23: 24 | G23: 12000 | K23: {=IF(L23="","", IFERROR(INDEX(Barang!$A$2:$A$10001, MATCH(L23, Barang!$B$2:$B$10001, 0)), "Tidak ditemukan"))} | M23: {=IF(L23="","", IFERROR(INDEX(Barang!$C$2:$C$10001, MATCH(L23, Barang!$B$2:$B$10001, 0)), ""))} | N23: {=IF(L23="","", IFERROR(INDEX(Barang!$E$2:$E$10001, MATCH(L23, Barang!$B$2:$B$10001, 0)), ""))} | P23: {=IF(L23="","", IFERROR(INDEX(Barang!$F$2:$F$10001, MATCH(L23, Barang!$B$2:$B$10001, 0)) * O23, ""))} | S23: - | T23: -
A24: 45943 | B24: {=IF(C24="","", IFERROR(INDEX(Barang!$A$2:$A$10001, MATCH(C24, Barang!$B$2:$B$10001, 0)), "Tidak ditemukan"))} -> GL1001 | C24: Gula 1kg | D24: Bumbu | E24: kg | F24: 50 | G24: 825000 | K24: {=IF(L24="","", IFERROR(INDEX(Barang!$A$2:$A$10001, MATCH(L24, Barang!$B$2:$B$10001, 0)), "Tidak ditemukan"))} | M24: {=IF(L24="","", IFERROR(INDEX(Barang!$C$2:$C$10001, MATCH(L24, Barang!$B$2:$B$10001, 0)), ""))} | N24: {=IF(L24="","", IFERROR(INDEX(Barang!$E$2:$E$10001, MATCH(L24, Barang!$B$2:$B$10001, 0)), ""))} | P24: {=IF(L24="","", IFERROR(INDEX(Barang!$F$2:$F$10001, MATCH(L24, Barang!$B$2:$B$10001, 0)) * O24, ""))} | S24: - | T24: -
B25: {=IF(C25="","", IFERROR(INDEX(Barang!$A$2:$A$10001, MATCH(C25, Barang!$B$2:$B$10001, 0)), "Tidak ditemukan"))} -> TLR2 | C25: Telur 1/2 | D25: Makanan | E25: kg | F25: 10 | G25: 310000 | K25: {=IF(L25="","", IFERROR(INDEX(Barang!$A$2:$A$10001, MATCH(L25, Barang!$B$2:$B$10001, 0)), "Tidak ditemukan"))} | M25: {=IF(L25="","", IFERROR(INDEX(Barang!$C$2:$C$10001, MATCH(L25, Barang!$B$2:$B$10001, 0)), ""))} | N25: {=IF(L25="","", IFERROR(INDEX(Barang!$E$2:$E$10001, MATCH(L25, Barang!$B$2:$B$10001, 0)), ""))} | P25: {=IF(L25="","", IFERROR(INDEX(Barang!$F$2:$F$10001, MATCH(L25, Barang!$B$2:$B$10001, 0)) * O25, ""))} | S25: - | T25: -
B26: {=IF(C26="","", IFERROR(INDEX(Barang!$A$2:$A$10001, MATCH(C26, Barang!$B$2:$B$10001, 0)), "Tidak ditemukan"))} -> THD001 | C26: Teh Dandang | D26: Minuman | E26: pcs | F26: 12 | G26: 24000 | K26: {=IF(L26="","", IFERROR(INDEX(Barang!$A$2:$A$10001, MATCH(L26, Barang!$B$2:$B$10001, 0)), "Tidak ditemukan"))} | M26: {=IF(L26="","", IFERROR(INDEX(Barang!$C$2:$C$10001, MATCH(L26, Barang!$B$2:$B$10001, 0)), ""))} | N26: {=IF(L26="","", IFERROR(INDEX(Barang!$E$2:$E$10001, MATCH(L26, Barang!$B$2:$B$10001, 0)), ""))} | P26: {=IF(L26="","", IFERROR(INDEX(Barang!$F$2:$F$10001, MATCH(L26, Barang!$B$2:$B$10001, 0)) * O26, ""))} | S26: - | T26: -
B27: {=IF(C27="","", IFERROR(INDEX(Barang!$A$2:$A$10001, MATCH(C27, Barang!$B$2:$B$10001, 0)), "Tidak ditemukan"))} -> KPH001 | C27: Kopi hitam | D27: Minuman | E27: pcs | F27: 24 | G27: 24000 | K27: {=IF(L27="","", IFERROR(INDEX(Barang!$A$2:$A$10001, MATCH(L27, Barang!$B$2:$B$10001, 0)), "Tidak ditemukan"))} | M27: {=IF(L27="","", IFERROR(INDEX(Barang!$C$2:$C$10001, MATCH(L27, Barang!$B$2:$B$10001, 0)), ""))} | N27: {=IF(L27="","", IFERROR(INDEX(Barang!$E$2:$E$10001, MATCH(L27, Barang!$B$2:$B$10001, 0)), ""))} | P27: {=IF(L27="","", IFERROR(INDEX(Barang!$F$2:$F$10001, MATCH(L27, Barang!$B$2:$B$10001, 0)) * O27, ""))} | S27: - | T27: -
B28: {=IF(C28="","", IFERROR(INDEX(Barang!$A$2:$A$10001, MATCH(C28, Barang!$B$2:$B$10001, 0)), "Tidak ditemukan"))} -> RPK001 | C28: Rapika | D28: Detergen | E28: pcs | F28: 10 | G28: 50000 | K28: {=IF(L28="","", IFERROR(INDEX(Barang!$A$2:$A$10001, MATCH(L28, Barang!$B$2:$B$10001, 0)), "Tidak ditemukan"))} | M28: {=IF(L28="","", IFERROR(INDEX(Barang!$C$2:$C$10001, MATCH(L28, Barang!$B$2:$B$10001, 0)), ""))} | N28: {=IF(L28="","", IFERROR(INDEX(Barang!$E$2:$E$10001, MATCH(L28, Barang!$B$2:$B$10001, 0)), ""))} | P28: {=IF(L28="","", IFERROR(INDEX(Barang!$F$2:$F$10001, MATCH(L28, Barang!$B$2:$B$10001, 0)) * O28, ""))} | S28: - | T28: -
B29: {=IF(C29="","", IFERROR(INDEX(Barang!$A$2:$A$10001, MATCH(C29, Barang!$B$2:$B$10001, 0)), "Tidak ditemukan"))} -> MSK001 | C29: Masako | D29: Bumbu | E29: pcs | F29: 20 | G29: 10000 | K29: {=IF(L29="","", IFERROR(INDEX(Barang!$A$2:$A$10001, MATCH(L29, Barang!$B$2:$B$10001, 0)), "Tidak ditemukan"))} | M29: {=IF(L29="","", IFERROR(INDEX(Barang!$C$2:$C$10001, MATCH(L29, Barang!$B$2:$B$10001, 0)), ""))} | N29: {=IF(L29="","", IFERROR(INDEX(Barang!$E$2:$E$10001, MATCH(L29, Barang!$B$2:$B$10001, 0)), ""))} | P29: {=IF(L29="","", IFERROR(INDEX(Barang!$F$2:$F$10001, MATCH(L29, Barang!$B$2:$B$10001, 0)) * O29, ""))} | S29: - | T29: -
A30: 45944 | B30: {=IF(C30="","", IFERROR(INDEX(Barang!$A$2:$A$10001, MATCH(C30, Barang!$B$2:$B$10001, 0)), "Tidak ditemukan"))} -> MGR001 | C30: Mie Goreng | D30: Makanan | E30: pcs | F30: 40 | G30: 140000 | K30: {=IF(L30="","", IFERROR(INDEX(Barang!$A$2:$A$10001, MATCH(L30, Barang!$B$2:$B$10001, 0)), "Tidak ditemukan"))} | M30: {=IF(L30="","", IFERROR(INDEX(Barang!$C$2:$C$10001, MATCH(L30, Barang!$B$2:$B$10001, 0)), ""))} | N30: {=IF(L30="","", IFERROR(INDEX(Barang!$E$2:$E$10001, MATCH(L30, Barang!$B$2:$B$10001, 0)), ""))} | P30: {=IF(L30="","", IFERROR(INDEX(Barang!$F$2:$F$10001, MATCH(L30, Barang!$B$2:$B$10001, 0)) * O30, ""))} | S30: - | T30: -
B31: {=IF(C31="","", IFERROR(INDEX(Barang!$A$2:$A$10001, MATCH(C31, Barang!$B$2:$B$10001, 0)), "Tidak ditemukan"))} -> MKH001 | C31: Mie Kuah | D31: Makanan | E31: pcs | F31: 40 | G31: 120000 | K31: {=IF(L31="","", IFERROR(INDEX(Barang!$A$2:$A$10001, MATCH(L31, Barang!$B$2:$B$10001, 0)), "Tidak ditemukan"))} | M31: {=IF(L31="","", IFERROR(INDEX(Barang!$C$2:$C$10001, MATCH(L31, Barang!$B$2:$B$10001, 0)), ""))} | N31: {=IF(L31="","", IFERROR(INDEX(Barang!$E$2:$E$10001, MATCH(L31, Barang!$B$2:$B$10001, 0)), ""))} | P31: {=IF(L31="","", IFERROR(INDEX(Barang!$F$2:$F$10001, MATCH(L31, Barang!$B$2:$B$10001, 0)) * O31, ""))} | S31: - | T31: -
B32: {=IF(C32="","", IFERROR(INDEX(Barang!$A$2:$A$10001, MATCH(C32, Barang!$B$2:$B$10001, 0)), "Tidak ditemukan"))} -> KB001 | C32: Kuah Bakso | D32: Bumbu | E32: pcs | F32: 10 | G32: 5000 | K32: {=IF(L32="","", IFERROR(INDEX(Barang!$A$2:$A$10001, MATCH(L32, Barang!$B$2:$B$10001, 0)), "Tidak ditemukan"))} | M32: {=IF(L32="","", IFERROR(INDEX(Barang!$C$2:$C$10001, MATCH(L32, Barang!$B$2:$B$10001, 0)), ""))} | N32: {=IF(L32="","", IFERROR(INDEX(Barang!$E$2:$E$10001, MATCH(L32, Barang!$B$2:$B$10001, 0)), ""))} | P32: {=IF(L32="","", IFERROR(INDEX(Barang!$F$2:$F$10001, MATCH(L32, Barang!$B$2:$B$10001, 0)) * O32, ""))} | S32: - | T32: -
B33: {=IF(C33="","", IFERROR(INDEX(Barang!$A$2:$A$10001, MATCH(C33, Barang!$B$2:$B$10001, 0)), "Tidak ditemukan"))} -> TPL2 | C33: Tropical 2Lt | D33: Sembako | E33: pcs | F33: 20 | G33: 800000 | K33: {=IF(L33="","", IFERROR(INDEX(Barang!$A$2:$A$10001, MATCH(L33, Barang!$B$2:$B$10001, 0)), "Tidak ditemukan"))} | M33: {=IF(L33="","", IFERROR(INDEX(Barang!$C$2:$C$10001, MATCH(L33, Barang!$B$2:$B$10001, 0)), ""))} | N33: {=IF(L33="","", IFERROR(INDEX(Barang!$E$2:$E$10001, MATCH(L33, Barang!$B$2:$B$10001, 0)), ""))} | P33: {=IF(L33="","", IFERROR(INDEX(Barang!$F$2:$F$10001, MATCH(L33, Barang!$B$2:$B$10001, 0)) * O33, ""))} | S33: - | T33: -
B34: {=IF(C34="","", IFERROR(INDEX(Barang!$A$2:$A$10001, MATCH(C34, Barang!$B$2:$B$10001, 0)), "Tidak ditemukan"))} -> TLR2 | C34: Telur 1/2 | D34: Sembako | E34: kg | F34: 30 | G34: 960000 | K34: {=IF(L34="","", IFERROR(INDEX(Barang!$A$2:$A$10001, MATCH(L34, Barang!$B$2:$B$10001, 0)), "Tidak ditemukan"))} | M34: {=IF(L34="","", IFERROR(INDEX(Barang!$C$2:$C$10001, MATCH(L34, Barang!$B$2:$B$10001, 0)), ""))} | N34: {=IF(L34="","", IFERROR(INDEX(Barang!$E$2:$E$10001, MATCH(L34, Barang!$B$2:$B$10001, 0)), ""))} | P34: {=IF(L34="","", IFERROR(INDEX(Barang!$F$2:$F$10001, MATCH(L34, Barang!$B$2:$B$10001, 0)) * O34, ""))} | S34: - | T34: -
B35: {=IF(C35="","", IFERROR(INDEX(Barang!$A$2:$A$10001, MATCH(C35, Barang!$B$2:$B$10001, 0)), "Tidak ditemukan"))} -> MSK001 | C35: Masako | D35: Bumbu | E35: pcs | F35: 20 | G35: 10000 | K35: {=IF(L35="","", IFERROR(INDEX(Barang!$A$2:$A$10001, MATCH(L35, Barang!$B$2:$B$10001, 0)), "Tidak ditemukan"))} | M35: {=IF(L35="","", IFERROR(INDEX(Barang!$C$2:$C$10001, MATCH(L35, Barang!$B$2:$B$10001, 0)), ""))} | N35: {=IF(L35="","", IFERROR(INDEX(Barang!$E$2:$E$10001, MATCH(L35, Barang!$B$2:$B$10001, 0)), ""))} | P35: {=IF(L35="","", IFERROR(INDEX(Barang!$F$2:$F$10001, MATCH(L35, Barang!$B$2:$B$10001, 0)) * O35, ""))} | S35: - | T35: -
A36: 45945 | B36: {=IF(C36="","", IFERROR(INDEX(Barang!$A$2:$A$10001, MATCH(C36, Barang!$B$2:$B$10001, 0)), "Tidak ditemukan"))} -> MKH001 | C36: Mie Kuah | D36: Makanan | E36: pcs | F36: 40 | G36: 120000 | K36: {=IF(L36="","", IFERROR(INDEX(Barang!$A$2:$A$10001, MATCH(L36, Barang!$B$2:$B$10001, 0)), "Tidak ditemukan"))} | M36: {=IF(L36="","", IFERROR(INDEX(Barang!$C$2:$C$10001, MATCH(L36, Barang!$B$2:$B$10001, 0)), ""))} | N36: {=IF(L36="","", IFERROR(INDEX(Barang!$E$2:$E$10001, MATCH(L36, Barang!$B$2:$B$10001, 0)), ""))} | P36: {=IF(L36="","", IFERROR(INDEX(Barang!$F$2:$F$10001, MATCH(L36, Barang!$B$2:$B$10001, 0)) * O36, ""))} | S36: - | T36: -
B37: {=IF(C37="","", IFERROR(INDEX(Barang!$A$2:$A$10001, MATCH(C37, Barang!$B$2:$B$10001, 0)), "Tidak ditemukan"))} -> GRR001 | C37: Goriorio | D37: Makanan | E37: pcs | F37: 24 | G37: 24000 | K37: {=IF(L37="","", IFERROR(INDEX(Barang!$A$2:$A$10001, MATCH(L37, Barang!$B$2:$B$10001, 0)), "Tidak ditemukan"))} | M37: {=IF(L37="","", IFERROR(INDEX(Barang!$C$2:$C$10001, MATCH(L37, Barang!$B$2:$B$10001, 0)), ""))} | N37: {=IF(L37="","", IFERROR(INDEX(Barang!$E$2:$E$10001, MATCH(L37, Barang!$B$2:$B$10001, 0)), ""))} | P37: {=IF(L37="","", IFERROR(INDEX(Barang!$F$2:$F$10001, MATCH(L37, Barang!$B$2:$B$10001, 0)) * O37, ""))} | S37: - | T37: -
B38: {=IF(C38="","", IFERROR(INDEX(Barang!$A$2:$A$10001, MATCH(C38, Barang!$B$2:$B$10001, 0)), "Tidak ditemukan"))} -> TLR2 | C38: Telur 1/2 | D38: Makanan | E38: kg | F38: 50 | G38: 1555000 | K38: {=IF(L38="","", IFERROR(INDEX(Barang!$A$2:$A$10001, MATCH(L38, Barang!$B$2:$B$10001, 0)), "Tidak ditemukan"))} | M38: {=IF(L38="","", IFERROR(INDEX(Barang!$C$2:$C$10001, MATCH(L38, Barang!$B$2:$B$10001, 0)), ""))} | N38: {=IF(L38="","", IFERROR(INDEX(Barang!$E$2:$E$10001, MATCH(L38, Barang!$B$2:$B$10001, 0)), ""))} | P38: {=IF(L38="","", IFERROR(INDEX(Barang!$F$2:$F$10001, MATCH(L38, Barang!$B$2:$B$10001, 0)) * O38, ""))} | S38: - | T38: -
B39: {=IF(C39="","", IFERROR(INDEX(Barang!$A$2:$A$10001, MATCH(C39, Barang!$B$2:$B$10001, 0)), "Tidak ditemukan"))} -> RTP001 | C39: Roti Pia | D39: Makanan | E39: pcs | F39: 10 | G39: 20000 | K39: {=IF(L39="","", IFERROR(INDEX(Barang!$A$2:$A$10001, MATCH(L39, Barang!$B$2:$B$10001, 0)), "Tidak ditemukan"))} | M39: {=IF(L39="","", IFERROR(INDEX(Barang!$C$2:$C$10001, MATCH(L39, Barang!$B$2:$B$10001, 0)), ""))} | N39: {=IF(L39="","", IFERROR(INDEX(Barang!$E$2:$E$10001, MATCH(L39, Barang!$B$2:$B$10001, 0)), ""))} | P39: {=IF(L39="","", IFERROR(INDEX(Barang!$F$2:$F$10001, MATCH(L39, Barang!$B$2:$B$10001, 0)) * O39, ""))} | S39: - | T39: -
B40: {=IF(C40="","", IFERROR(INDEX(Barang!$A$2:$A$10001, MATCH(C40, Barang!$B$2:$B$10001, 0)), "Tidak ditemukan"))} -> KPH001 | C40: Kopi hitam | D40: Minuman | E40: pcs | F40: 50 | G40: 50000 | K40: {=IF(L40="","", IFERROR(INDEX(Barang!$A$2:$A$10001, MATCH(L40, Barang!$B$2:$B$10001, 0)), "Tidak ditemukan"))} | M40: {=IF(L40="","", IFERROR(INDEX(Barang!$C$2:$C$10001, MATCH(L40, Barang!$B$2:$B$10001, 0)), ""))} | N40: {=IF(L40="","", IFERROR(INDEX(Barang!$E$2:$E$10001, MATCH(L40, Barang!$B$2:$B$10001, 0)), ""))} | P40: {=IF(L40="","", IFERROR(INDEX(Barang!$F$2:$F$10001, MATCH(L40, Barang!$B$2:$B$10001, 0)) * O40, ""))} | S40: - | T40: -
...

Sheet 2026
A1: Tanggal | B1: Kode Barang | C1: Nama Barang | D1: Kategori | E1: Satuan | F1: Jual | G1: Harga Jual | H1: Stok Awal | J1: Tanggal | K1: Kode Barang | L1: Nama Barang | M1: Kategori | N1: Satuan | O1: Kulak | P1: Harga Jual | Q1: Harga Kulak | R1: Stok Akhir | S1: Minimal Stok | T1: Supplier
A2: 46023 | B2: {=IF(C2="","", IFERROR(INDEX(Barang!$A$2:$A$10001, MATCH(C2, Barang!$B$2:$B$10001, 0)), "Tidak ditemukan"))} -> GPT001 | C2: Gery potato | D2: {=IF(C2="","", IFERROR(INDEX(Barang!$C$2:$C$10001, MATCH(C2, Barang!$B$2:$B$10001, 0)), ""))} -> Makanan | E2: {=IF(C2="","", IFERROR(INDEX(Barang!$E$2:$E$10001, MATCH(C2, Barang!$B$2:$B$10001, 0)), ""))} -> pcs | F2: 3 | G2: {=IF(C2="","", IFERROR(INDEX(Barang!$F$2:$F$10001, MATCH(C2, Barang!$B$2:$B$10001, 0)) * F2, ""))} -> 3000 | R2: =#REF!-#REF!+O2 -> #REF! | S2: - | T2: -
B3: {=IF(C3="","", IFERROR(INDEX(Barang!$A$2:$A$10001, MATCH(C3, Barang!$B$2:$B$10001, 0)), "Tidak ditemukan"))} -> CL1001 | C3: Chocolatos 1000 | D3: {=IF(C3="","", IFERROR(INDEX(Barang!$C$2:$C$10001, MATCH(C3, Barang!$B$2:$B$10001, 0)), ""))} -> Makanan | E3: {=IF(C3="","", IFERROR(INDEX(Barang!$E$2:$E$10001, MATCH(C3, Barang!$B$2:$B$10001, 0)), ""))} -> pcs | F3: 2 | G3: {=IF(C3="","", IFERROR(INDEX(Barang!$F$2:$F$10001, MATCH(C3, Barang!$B$2:$B$10001, 0)) * F3, ""))} -> 2000 | R3: =#REF!-#REF!+O3 -> #REF! | S3: - | T3: -
B4: {=IF(C4="","", IFERROR(INDEX(Barang!$A$2:$A$10001, MATCH(C4, Barang!$B$2:$B$10001, 0)), "Tidak ditemukan"))} -> THD001 | C4: Teh dandang | D4: {=IF(C4="","", IFERROR(INDEX(Barang!$C$2:$C$10001, MATCH(C4, Barang!$B$2:$B$10001, 0)), ""))} -> Minuman | E4: {=IF(C4="","", IFERROR(INDEX(Barang!$E$2:$E$10001, MATCH(C4, Barang!$B$2:$B$10001, 0)), ""))} -> pcs | F4: 2 | G4: {=IF(C4="","", IFERROR(INDEX(Barang!$F$2:$F$10001, MATCH(C4, Barang!$B$2:$B$10001, 0)) * F4, ""))} -> 4000 | R4: =#REF!-#REF!+O4 -> #REF! | S4: - | T4: -
B5: {=IF(C5="","", IFERROR(INDEX(Barang!$A$2:$A$10001, MATCH(C5, Barang!$B$2:$B$10001, 0)), "Tidak ditemukan"))} -> TLR2 | C5: Telur 1/2 | D5: {=IF(C5="","", IFERROR(INDEX(Barang!$C$2:$C$10001, MATCH(C5, Barang!$B$2:$B$10001, 0)), ""))} -> Sembako | E5: {=IF(C5="","", IFERROR(INDEX(Barang!$E$2:$E$10001, MATCH(C5, Barang!$B$2:$B$10001, 0)), ""))} -> kg | F5: 10 | G5: {=IF(C5="","", IFERROR(INDEX(Barang!$F$2:$F$10001, MATCH(C5, Barang!$B$2:$B$10001, 0)) * F5, ""))} -> 155000 | R5: =#REF!-#REF!+O5 -> #REF! | S5: - | T5: -
B6: {=IF(C6="","", IFERROR(INDEX(Barang!$A$2:$A$10001, MATCH(C6, Barang!$B$2:$B$10001, 0)), "Tidak ditemukan"))} -> PLS002 | C6: Pilus | D6: {=IF(C6="","", IFERROR(INDEX(Barang!$C$2:$C$10001, MATCH(C6, Barang!$B$2:$B$10001, 0)), ""))} -> Makanan | E6: {=IF(C6="","", IFERROR(INDEX(Barang!$E$2:$E$10001, MATCH(C6, Barang!$B$2:$B$10001, 0)), ""))} -> pcs | F6: 1 | G6: {=IF(C6="","", IFERROR(INDEX(Barang!$F$2:$F$10001, MATCH(C6, Barang!$B$2:$B$10001, 0)) * F6, ""))} -> 1000 | R6: =#REF!-#REF!+O6 -> #REF! | S6: - | T6: -
B7: {=IF(C7="","", IFERROR(INDEX(Barang!$A$2:$A$10001, MATCH(C7, Barang!$B$2:$B$10001, 0)), "Tidak ditemukan"))} -> MGR001 | C7: Mie goreng | D7: {=IF(C7="","", IFERROR(INDEX(Barang!$C$2:$C$10001, MATCH(C7, Barang!$B$2:$B$10001, 0)), ""))} -> Makanan | E7: {=IF(C7="","", IFERROR(INDEX(Barang!$E$2:$E$10001, MATCH(C7, Barang!$B$2:$B$10001, 0)), ""))} -> pcs | F7: 10 | G7: {=IF(C7="","", IFERROR(INDEX(Barang!$F$2:$F$10001, MATCH(C7, Barang!$B$2:$B$10001, 0)) * F7, ""))} -> 35000 | R7: =#REF!-#REF!+O7 -> #REF! | S7: - | T7: -
B8: {=IF(C8="","", IFERROR(INDEX(Barang!$A$2:$A$10001, MATCH(C8, Barang!$B$2:$B$10001, 0)), "Tidak ditemukan"))} -> IDM002 | C8: Indomilk | D8: {=IF(C8="","", IFERROR(INDEX(Barang!$C$2:$C$10001, MATCH(C8, Barang!$B$2:$B$10001, 0)), ""))} -> Minuman | E8: {=IF(C8="","", IFERROR(INDEX(Barang!$E$2:$E$10001, MATCH(C8, Barang!$B$2:$B$10001, 0)), ""))} -> pcs | F8: 2 | G8: {=IF(C8="","", IFERROR(INDEX(Barang!$F$2:$F$10001, MATCH(C8, Barang!$B$2:$B$10001, 0)) * F8, ""))} -> 3000 | R8: =#REF!-#REF!+O8 -> #REF! | S8: - | T8: -
B9: {=IF(C9="","", IFERROR(INDEX(Barang!$A$2:$A$10001, MATCH(C9, Barang!$B$2:$B$10001, 0)), "Tidak ditemukan"))} -> SG7001 | C9: Sari gandum 7 | D9: {=IF(C9="","", IFERROR(INDEX(Barang!$C$2:$C$10001, MATCH(C9, Barang!$B$2:$B$10001, 0)), ""))} -> Makanan | E9: {=IF(C9="","", IFERROR(INDEX(Barang!$E$2:$E$10001, MATCH(C9, Barang!$B$2:$B$10001, 0)), ""))} -> pcs | F9: 1 | G9: {=IF(C9="","", IFERROR(INDEX(Barang!$F$2:$F$10001, MATCH(C9, Barang!$B$2:$B$10001, 0)) * F9, ""))} -> 7500 | R9: =#REF!-#REF!+O9 -> #REF! | S9: - | T9: -
B10: {=IF(C10="","", IFERROR(INDEX(Barang!$A$2:$A$10001, MATCH(C10, Barang!$B$2:$B$10001, 0)), "Tidak ditemukan"))} -> TRS001 | C10: Terasi | D10: {=IF(C10="","", IFERROR(INDEX(Barang!$C$2:$C$10001, MATCH(C10, Barang!$B$2:$B$10001, 0)), ""))} -> Bumbu | E10: {=IF(C10="","", IFERROR(INDEX(Barang!$E$2:$E$10001, MATCH(C10, Barang!$B$2:$B$10001, 0)), ""))} -> pcs | F10: 5 | G10: {=IF(C10="","", IFERROR(INDEX(Barang!$F$2:$F$10001, MATCH(C10, Barang!$B$2:$B$10001, 0)) * F10, ""))} -> 2500 | R10: =#REF!-#REF!+O10 -> #REF! | S10: - | T10: -
A11: 46024 | B11: {=IF(C11="","", IFERROR(INDEX(Barang!$A$2:$A$10001, MATCH(C11, Barang!$B$2:$B$10001, 0)), "Tidak ditemukan"))} -> CL1001 | C11: Chocolatos 1000 | D11: {=IF(C11="","", IFERROR(INDEX(Barang!$C$2:$C$10001, MATCH(C11, Barang!$B$2:$B$10001, 0)), ""))} -> Makanan | E11: {=IF(C11="","", IFERROR(INDEX(Barang!$E$2:$E$10001, MATCH(C11, Barang!$B$2:$B$10001, 0)), ""))} -> pcs | F11: 1 | G11: {=IF(C11="","", IFERROR(INDEX(Barang!$F$2:$F$10001, MATCH(C11, Barang!$B$2:$B$10001, 0)) * F11, ""))} -> 1000 | R11: =#REF!-#REF!+O11 -> #REF! | S11: - | T11: -
B12: {=IF(C12="","", IFERROR(INDEX(Barang!$A$2:$A$10001, MATCH(C12, Barang!$B$2:$B$10001, 0)), "Tidak ditemukan"))} -> Tidak ditemukan | C12: Fruta gummy | D12: {=IF(C12="","", IFERROR(INDEX(Barang!$C$2:$C$10001, MATCH(C12, Barang!$B$2:$B$10001, 0)), ""))} | E12: {=IF(C12="","", IFERROR(INDEX(Barang!$E$2:$E$10001, MATCH(C12, Barang!$B$2:$B$10001, 0)), ""))} | F12: 3 | G12: {=IF(C12="","", IFERROR(INDEX(Barang!$F$2:$F$10001, MATCH(C12, Barang!$B$2:$B$10001, 0)) * F12, ""))} | R12: =#REF!-#REF!+O12 -> #REF! | S12: - | T12: -
B13: {=IF(C13="","", IFERROR(INDEX(Barang!$A$2:$A$10001, MATCH(C13, Barang!$B$2:$B$10001, 0)), "Tidak ditemukan"))} -> STS | C13: Santan sasa | D13: {=IF(C13="","", IFERROR(INDEX(Barang!$C$2:$C$10001, MATCH(C13, Barang!$B$2:$B$10001, 0)), ""))} -> Bumbu | E13: {=IF(C13="","", IFERROR(INDEX(Barang!$E$2:$E$10001, MATCH(C13, Barang!$B$2:$B$10001, 0)), ""))} -> pcs | F13: 1 | G13: {=IF(C13="","", IFERROR(INDEX(Barang!$F$2:$F$10001, MATCH(C13, Barang!$B$2:$B$10001, 0)) * F13, ""))} -> 5500 | R13: =#REF!-#REF!+O13 -> #REF! | S13: - | T13: -
B14: {=IF(C14="","", IFERROR(INDEX(Barang!$A$2:$A$10001, MATCH(C14, Barang!$B$2:$B$10001, 0)), "Tidak ditemukan"))} -> GPT001 | C14: Gery potato | D14: {=IF(C14="","", IFERROR(INDEX(Barang!$C$2:$C$10001, MATCH(C14, Barang!$B$2:$B$10001, 0)), ""))} -> Makanan | E14: {=IF(C14="","", IFERROR(INDEX(Barang!$E$2:$E$10001, MATCH(C14, Barang!$B$2:$B$10001, 0)), ""))} -> pcs | F14: 3 | G14: {=IF(C14="","", IFERROR(INDEX(Barang!$F$2:$F$10001, MATCH(C14, Barang!$B$2:$B$10001, 0)) * F14, ""))} -> 3000 | R14: =#REF!-#REF!+O14 -> #REF! | S14: - | T14: -
B15: {=IF(C15="","", IFERROR(INDEX(Barang!$A$2:$A$10001, MATCH(C15, Barang!$B$2:$B$10001, 0)), "Tidak ditemukan"))} -> CL5001 | C15: Chocolatos 500 | D15: {=IF(C15="","", IFERROR(INDEX(Barang!$C$2:$C$10001, MATCH(C15, Barang!$B$2:$B$10001, 0)), ""))} -> Makanan | E15: {=IF(C15="","", IFERROR(INDEX(Barang!$E$2:$E$10001, MATCH(C15, Barang!$B$2:$B$10001, 0)), ""))} -> pcs | F15: 1 | G15: {=IF(C15="","", IFERROR(INDEX(Barang!$F$2:$F$10001, MATCH(C15, Barang!$B$2:$B$10001, 0)) * F15, ""))} -> 500 | R15: =#REF!-#REF!+O15 -> #REF! | S15: - | T15: -
B16: {=IF(C16="","", IFERROR(INDEX(Barang!$A$2:$A$10001, MATCH(C16, Barang!$B$2:$B$10001, 0)), "Tidak ditemukan"))} -> MGR001 | C16: Mie goreng | D16: {=IF(C16="","", IFERROR(INDEX(Barang!$C$2:$C$10001, MATCH(C16, Barang!$B$2:$B$10001, 0)), ""))} -> Makanan | E16: {=IF(C16="","", IFERROR(INDEX(Barang!$E$2:$E$10001, MATCH(C16, Barang!$B$2:$B$10001, 0)), ""))} -> pcs | F16: 30 | G16: {=IF(C16="","", IFERROR(INDEX(Barang!$F$2:$F$10001, MATCH(C16, Barang!$B$2:$B$10001, 0)) * F16, ""))} -> 105000 | R16: =#REF!-#REF!+O16 -> #REF! | S16: - | T16: -
B17: {=IF(C17="","", IFERROR(INDEX(Barang!$A$2:$A$10001, MATCH(C17, Barang!$B$2:$B$10001, 0)), "Tidak ditemukan"))} -> GL1001 | C17: Gula 1kg | D17: {=IF(C17="","", IFERROR(INDEX(Barang!$C$2:$C$10001, MATCH(C17, Barang!$B$2:$B$10001, 0)), ""))} -> Sembako | E17: {=IF(C17="","", IFERROR(INDEX(Barang!$E$2:$E$10001, MATCH(C17, Barang!$B$2:$B$10001, 0)), ""))} -> kg | F17: 30 | G17: {=IF(C17="","", IFERROR(INDEX(Barang!$F$2:$F$10001, MATCH(C17, Barang!$B$2:$B$10001, 0)) * F17, ""))} -> 495000 | R17: =#REF!-#REF!+O17 -> #REF! | S17: - | T17: -
B18: {=IF(C18="","", IFERROR(INDEX(Barang!$A$2:$A$10001, MATCH(C18, Barang!$B$2:$B$10001, 0)), "Tidak ditemukan"))} -> PLP001 | C18: Pilus POP | D18: {=IF(C18="","", IFERROR(INDEX(Barang!$C$2:$C$10001, MATCH(C18, Barang!$B$2:$B$10001, 0)), ""))} -> Makanan | E18: {=IF(C18="","", IFERROR(INDEX(Barang!$E$2:$E$10001, MATCH(C18, Barang!$B$2:$B$10001, 0)), ""))} -> pcs | F18: 1 | G18: {=IF(C18="","", IFERROR(INDEX(Barang!$F$2:$F$10001, MATCH(C18, Barang!$B$2:$B$10001, 0)) * F18, ""))} -> 2000 | R18: =#REF!-#REF!+O18 -> #REF! | S18: - | T18: -
B19: {=IF(C19="","", IFERROR(INDEX(Barang!$A$2:$A$10001, MATCH(C19, Barang!$B$2:$B$10001, 0)), "Tidak ditemukan"))} -> SBE001 | C19: Ekonomi colek | D19: {=IF(C19="","", IFERROR(INDEX(Barang!$C$2:$C$10001, MATCH(C19, Barang!$B$2:$B$10001, 0)), ""))} -> Detergen | E19: {=IF(C19="","", IFERROR(INDEX(Barang!$E$2:$E$10001, MATCH(C19, Barang!$B$2:$B$10001, 0)), ""))} -> pcs | F19: 1 | G19: {=IF(C19="","", IFERROR(INDEX(Barang!$F$2:$F$10001, MATCH(C19, Barang!$B$2:$B$10001, 0)) * F19, ""))} -> 2000 | R19: =#REF!-#REF!+O19 -> #REF! | S19: - | T19: -
B20: {=IF(C20="","", IFERROR(INDEX(Barang!$A$2:$A$10001, MATCH(C20, Barang!$B$2:$B$10001, 0)), "Tidak ditemukan"))} -> GCC001 | C20: Garuda crunchy | D20: {=IF(C20="","", IFERROR(INDEX(Barang!$C$2:$C$10001, MATCH(C20, Barang!$B$2:$B$10001, 0)), ""))} -> Makanan | E20: {=IF(C20="","", IFERROR(INDEX(Barang!$E$2:$E$10001, MATCH(C20, Barang!$B$2:$B$10001, 0)), ""))} -> pcs | F20: 1 | G20: {=IF(C20="","", IFERROR(INDEX(Barang!$F$2:$F$10001, MATCH(C20, Barang!$B$2:$B$10001, 0)) * F20, ""))} -> 2000 | R20: =#REF!-#REF!+O20 -> #REF! | S20: - | T20: -
B21: {=IF(C21="","", IFERROR(INDEX(Barang!$A$2:$A$10001, MATCH(C21, Barang!$B$2:$B$10001, 0)), "Tidak ditemukan"))} -> PLS002 | C21: Pilus | D21: {=IF(C21="","", IFERROR(INDEX(Barang!$C$2:$C$10001, MATCH(C21, Barang!$B$2:$B$10001, 0)), ""))} -> Makanan | E21: {=IF(C21="","", IFERROR(INDEX(Barang!$E$2:$E$10001, MATCH(C21, Barang!$B$2:$B$10001, 0)), ""))} -> pcs | F21: 2 | G21: {=IF(C21="","", IFERROR(INDEX(Barang!$F$2:$F$10001, MATCH(C21, Barang!$B$2:$B$10001, 0)) * F21, ""))} -> 2000 | R21: =#REF!-#REF!+O21 -> #REF! | S21: - | T21: -
B22: {=IF(C22="","", IFERROR(INDEX(Barang!$A$2:$A$10001, MATCH(C22, Barang!$B$2:$B$10001, 0)), "Tidak ditemukan"))} -> SNK001 | C22: Snack | D22: {=IF(C22="","", IFERROR(INDEX(Barang!$C$2:$C$10001, MATCH(C22, Barang!$B$2:$B$10001, 0)), ""))} -> Makanan | E22: {=IF(C22="","", IFERROR(INDEX(Barang!$E$2:$E$10001, MATCH(C22, Barang!$B$2:$B$10001, 0)), ""))} -> pcs | F22: 1 | G22: {=IF(C22="","", IFERROR(INDEX(Barang!$F$2:$F$10001, MATCH(C22, Barang!$B$2:$B$10001, 0)) * F22, ""))} -> 2000 | R22: =#REF!-#REF!+O22 -> #REF! | S22: - | T22: -
B23: {=IF(C23="","", IFERROR(INDEX(Barang!$A$2:$A$10001, MATCH(C23, Barang!$B$2:$B$10001, 0)), "Tidak ditemukan"))} -> PTS001 | C23: Piattos | D23: {=IF(C23="","", IFERROR(INDEX(Barang!$C$2:$C$10001, MATCH(C23, Barang!$B$2:$B$10001, 0)), ""))} -> Makanan | E23: {=IF(C23="","", IFERROR(INDEX(Barang!$E$2:$E$10001, MATCH(C23, Barang!$B$2:$B$10001, 0)), ""))} -> pcs | F23: 1 | G23: {=IF(C23="","", IFERROR(INDEX(Barang!$F$2:$F$10001, MATCH(C23, Barang!$B$2:$B$10001, 0)) * F23, ""))} -> 2000 | K23: {=IF(L23="","", IFERROR(INDEX(Barang!$A$2:$A$10001, MATCH(L23, Barang!$B$2:$B$10001, 0)), "Tidak ditemukan"))} | M23: {=IF(L23="","", IFERROR(INDEX(Barang!$C$2:$C$10001, MATCH(L23, Barang!$B$2:$B$10001, 0)), ""))} | N23: {=IF(L23="","", IFERROR(INDEX(Barang!$E$2:$E$10001, MATCH(L23, Barang!$B$2:$B$10001, 0)), ""))} | P23: {=IF(L23="","", IFERROR(INDEX(Barang!$F$2:$F$10001, MATCH(L23, Barang!$B$2:$B$10001, 0)) * O23, ""))} | R23: =#REF!-#REF!+O23 -> #REF! | S23: - | T23: -
B24: {=IF(C24="","", IFERROR(INDEX(Barang!$A$2:$A$10001, MATCH(C24, Barang!$B$2:$B$10001, 0)), "Tidak ditemukan"))} -> DSK01 | C24: Desaku rempah | D24: {=IF(C24="","", IFERROR(INDEX(Barang!$C$2:$C$10001, MATCH(C24, Barang!$B$2:$B$10001, 0)), ""))} -> Bumbu | E24: {=IF(C24="","", IFERROR(INDEX(Barang!$E$2:$E$10001, MATCH(C24, Barang!$B$2:$B$10001, 0)), ""))} -> pcs | F24: 1 | G24: {=IF(C24="","", IFERROR(INDEX(Barang!$F$2:$F$10001, MATCH(C24, Barang!$B$2:$B$10001, 0)) * F24, ""))} -> 1000 | K24: {=IF(L24="","", IFERROR(INDEX(Barang!$A$2:$A$10001, MATCH(L24, Barang!$B$2:$B$10001, 0)), "Tidak ditemukan"))} | M24: {=IF(L24="","", IFERROR(INDEX(Barang!$C$2:$C$10001, MATCH(L24, Barang!$B$2:$B$10001, 0)), ""))} | N24: {=IF(L24="","", IFERROR(INDEX(Barang!$E$2:$E$10001, MATCH(L24, Barang!$B$2:$B$10001, 0)), ""))} | P24: {=IF(L24="","", IFERROR(INDEX(Barang!$F$2:$F$10001, MATCH(L24, Barang!$B$2:$B$10001, 0)) * O24, ""))} | R24: =#REF!-#REF!+O24 -> #REF! | S24: - | T24: -
B25: {=IF(C25="","", IFERROR(INDEX(Barang!$A$2:$A$10001, MATCH(C25, Barang!$B$2:$B$10001, 0)), "Tidak ditemukan"))} -> KRS001 | C25: Kara santan | D25: {=IF(C25="","", IFERROR(INDEX(Barang!$C$2:$C$10001, MATCH(C25, Barang!$B$2:$B$10001, 0)), ""))} -> Bumbu | E25: {=IF(C25="","", IFERROR(INDEX(Barang!$E$2:$E$10001, MATCH(C25, Barang!$B$2:$B$10001, 0)), ""))} -> pcs | F25: 1 | G25: {=IF(C25="","", IFERROR(INDEX(Barang!$F$2:$F$10001, MATCH(C25, Barang!$B$2:$B$10001, 0)) * F25, ""))} -> 6500 | K25: {=IF(L25="","", IFERROR(INDEX(Barang!$A$2:$A$10001, MATCH(L25, Barang!$B$2:$B$10001, 0)), "Tidak ditemukan"))} | M25: {=IF(L25="","", IFERROR(INDEX(Barang!$C$2:$C$10001, MATCH(L25, Barang!$B$2:$B$10001, 0)), ""))} | N25: {=IF(L25="","", IFERROR(INDEX(Barang!$E$2:$E$10001, MATCH(L25, Barang!$B$2:$B$10001, 0)), ""))} | P25: {=IF(L25="","", IFERROR(INDEX(Barang!$F$2:$F$10001, MATCH(L25, Barang!$B$2:$B$10001, 0)) * O25, ""))} | R25: =#REF!-#REF!+O25 -> #REF! | S25: - | T25: -
B26: {=IF(C26="","", IFERROR(INDEX(Barang!$A$2:$A$10001, MATCH(C26, Barang!$B$2:$B$10001, 0)), "Tidak ditemukan"))} -> KCP001 | C26: Kecap | D26: {=IF(C26="","", IFERROR(INDEX(Barang!$C$2:$C$10001, MATCH(C26, Barang!$B$2:$B$10001, 0)), ""))} -> Bumbu | E26: {=IF(C26="","", IFERROR(INDEX(Barang!$E$2:$E$10001, MATCH(C26, Barang!$B$2:$B$10001, 0)), ""))} -> pcs | F26: 2 | G26: {=IF(C26="","", IFERROR(INDEX(Barang!$F$2:$F$10001, MATCH(C26, Barang!$B$2:$B$10001, 0)) * F26, ""))} -> 4000 | K26: {=IF(L26="","", IFERROR(INDEX(Barang!$A$2:$A$10001, MATCH(L26, Barang!$B$2:$B$10001, 0)), "Tidak ditemukan"))} | M26: {=IF(L26="","", IFERROR(INDEX(Barang!$C$2:$C$10001, MATCH(L26, Barang!$B$2:$B$10001, 0)), ""))} | N26: {=IF(L26="","", IFERROR(INDEX(Barang!$E$2:$E$10001, MATCH(L26, Barang!$B$2:$B$10001, 0)), ""))} | P26: {=IF(L26="","", IFERROR(INDEX(Barang!$F$2:$F$10001, MATCH(L26, Barang!$B$2:$B$10001, 0)) * O26, ""))} | R26: =#REF!-#REF!+O26 -> #REF! | S26: - | T26: -
B27: {=IF(C27="","", IFERROR(INDEX(Barang!$A$2:$A$10001, MATCH(C27, Barang!$B$2:$B$10001, 0)), "Tidak ditemukan"))} -> MSK001 | C27: Masako | D27: {=IF(C27="","", IFERROR(INDEX(Barang!$C$2:$C$10001, MATCH(C27, Barang!$B$2:$B$10001, 0)), ""))} -> Bumbu | E27: {=IF(C27="","", IFERROR(INDEX(Barang!$E$2:$E$10001, MATCH(C27, Barang!$B$2:$B$10001, 0)), ""))} -> pcs | F27: 20 | G27: {=IF(C27="","", IFERROR(INDEX(Barang!$F$2:$F$10001, MATCH(C27, Barang!$B$2:$B$10001, 0)) * F27, ""))} -> 10000 | K27: {=IF(L27="","", IFERROR(INDEX(Barang!$A$2:$A$10001, MATCH(L27, Barang!$B$2:$B$10001, 0)), "Tidak ditemukan"))} | M27: {=IF(L27="","", IFERROR(INDEX(Barang!$C$2:$C$10001, MATCH(L27, Barang!$B$2:$B$10001, 0)), ""))} | N27: {=IF(L27="","", IFERROR(INDEX(Barang!$E$2:$E$10001, MATCH(L27, Barang!$B$2:$B$10001, 0)), ""))} | P27: {=IF(L27="","", IFERROR(INDEX(Barang!$F$2:$F$10001, MATCH(L27, Barang!$B$2:$B$10001, 0)) * O27, ""))} | R27: =#REF!-#REF!+O27 -> #REF! | S27: - | T27: -
B28: {=IF(C28="","", IFERROR(INDEX(Barang!$A$2:$A$10001, MATCH(C28, Barang!$B$2:$B$10001, 0)), "Tidak ditemukan"))} -> CLB001 | C28: Chocolatos bubuk | D28: {=IF(C28="","", IFERROR(INDEX(Barang!$C$2:$C$10001, MATCH(C28, Barang!$B$2:$B$10001, 0)), ""))} -> Minuman | E28: {=IF(C28="","", IFERROR(INDEX(Barang!$E$2:$E$10001, MATCH(C28, Barang!$B$2:$B$10001, 0)), ""))} -> pcs | F28: 1 | G28: {=IF(C28="","", IFERROR(INDEX(Barang!$F$2:$F$10001, MATCH(C28, Barang!$B$2:$B$10001, 0)) * F28, ""))} -> 2500 | K28: {=IF(L28="","", IFERROR(INDEX(Barang!$A$2:$A$10001, MATCH(L28, Barang!$B$2:$B$10001, 0)), "Tidak ditemukan"))} | M28: {=IF(L28="","", IFERROR(INDEX(Barang!$C$2:$C$10001, MATCH(L28, Barang!$B$2:$B$10001, 0)), ""))} | N28: {=IF(L28="","", IFERROR(INDEX(Barang!$E$2:$E$10001, MATCH(L28, Barang!$B$2:$B$10001, 0)), ""))} | P28: {=IF(L28="","", IFERROR(INDEX(Barang!$F$2:$F$10001, MATCH(L28, Barang!$B$2:$B$10001, 0)) * O28, ""))} | R28: =#REF!-#REF!+O28 -> #REF! | S28: - | T28: -
B29: {=IF(C29="","", IFERROR(INDEX(Barang!$A$2:$A$10001, MATCH(C29, Barang!$B$2:$B$10001, 0)), "Tidak ditemukan"))} -> MKH001 | C29: Mie kuah | D29: {=IF(C29="","", IFERROR(INDEX(Barang!$C$2:$C$10001, MATCH(C29, Barang!$B$2:$B$10001, 0)), ""))} -> Makanan | E29: {=IF(C29="","", IFERROR(INDEX(Barang!$E$2:$E$10001, MATCH(C29, Barang!$B$2:$B$10001, 0)), ""))} -> pcs | F29: 10 | G29: {=IF(C29="","", IFERROR(INDEX(Barang!$F$2:$F$10001, MATCH(C29, Barang!$B$2:$B$10001, 0)) * F29, ""))} -> 35000 | K29: {=IF(L29="","", IFERROR(INDEX(Barang!$A$2:$A$10001, MATCH(L29, Barang!$B$2:$B$10001, 0)), "Tidak ditemukan"))} | M29: {=IF(L29="","", IFERROR(INDEX(Barang!$C$2:$C$10001, MATCH(L29, Barang!$B$2:$B$10001, 0)), ""))} | N29: {=IF(L29="","", IFERROR(INDEX(Barang!$E$2:$E$10001, MATCH(L29, Barang!$B$2:$B$10001, 0)), ""))} | P29: {=IF(L29="","", IFERROR(INDEX(Barang!$F$2:$F$10001, MATCH(L29, Barang!$B$2:$B$10001, 0)) * O29, ""))} | R29: =#REF!-#REF!+O29 -> #REF! | S29: - | T29: -
B30: {=IF(C30="","", IFERROR(INDEX(Barang!$A$2:$A$10001, MATCH(C30, Barang!$B$2:$B$10001, 0)), "Tidak ditemukan"))} -> SG7001 | C30: Sari gandum 7 | D30: {=IF(C30="","", IFERROR(INDEX(Barang!$C$2:$C$10001, MATCH(C30, Barang!$B$2:$B$10001, 0)), ""))} -> Makanan | E30: {=IF(C30="","", IFERROR(INDEX(Barang!$E$2:$E$10001, MATCH(C30, Barang!$B$2:$B$10001, 0)), ""))} -> pcs | F30: 1 | G30: {=IF(C30="","", IFERROR(INDEX(Barang!$F$2:$F$10001, MATCH(C30, Barang!$B$2:$B$10001, 0)) * F30, ""))} -> 7500 | K30: {=IF(L30="","", IFERROR(INDEX(Barang!$A$2:$A$10001, MATCH(L30, Barang!$B$2:$B$10001, 0)), "Tidak ditemukan"))} | M30: {=IF(L30="","", IFERROR(INDEX(Barang!$C$2:$C$10001, MATCH(L30, Barang!$B$2:$B$10001, 0)), ""))} | N30: {=IF(L30="","", IFERROR(INDEX(Barang!$E$2:$E$10001, MATCH(L30, Barang!$B$2:$B$10001, 0)), ""))} | P30: {=IF(L30="","", IFERROR(INDEX(Barang!$F$2:$F$10001, MATCH(L30, Barang!$B$2:$B$10001, 0)) * O30, ""))} | R30: =#REF!-#REF!+O30 -> #REF! | S30: - | T30: -
B31: {=IF(C31="","", IFERROR(INDEX(Barang!$A$2:$A$10001, MATCH(C31, Barang!$B$2:$B$10001, 0)), "Tidak ditemukan"))} -> IDM002 | C31: Indomilk | D31: {=IF(C31="","", IFERROR(INDEX(Barang!$C$2:$C$10001, MATCH(C31, Barang!$B$2:$B$10001, 0)), ""))} -> Minuman | E31: {=IF(C31="","", IFERROR(INDEX(Barang!$E$2:$E$10001, MATCH(C31, Barang!$B$2:$B$10001, 0)), ""))} -> pcs | F31: 6 | G31: {=IF(C31="","", IFERROR(INDEX(Barang!$F$2:$F$10001, MATCH(C31, Barang!$B$2:$B$10001, 0)) * F31, ""))} -> 9000 | K31: {=IF(L31="","", IFERROR(INDEX(Barang!$A$2:$A$10001, MATCH(L31, Barang!$B$2:$B$10001, 0)), "Tidak ditemukan"))} | M31: {=IF(L31="","", IFERROR(INDEX(Barang!$C$2:$C$10001, MATCH(L31, Barang!$B$2:$B$10001, 0)), ""))} | N31: {=IF(L31="","", IFERROR(INDEX(Barang!$E$2:$E$10001, MATCH(L31, Barang!$B$2:$B$10001, 0)), ""))} | P31: {=IF(L31="","", IFERROR(INDEX(Barang!$F$2:$F$10001, MATCH(L31, Barang!$B$2:$B$10001, 0)) * O31, ""))} | R31: =#REF!-#REF!+O31 -> #REF! | S31: - | T31: -
B32: {=IF(C32="","", IFERROR(INDEX(Barang!$A$2:$A$10001, MATCH(C32, Barang!$B$2:$B$10001, 0)), "Tidak ditemukan"))} -> RTP001 | C32: Roti pia | D32: {=IF(C32="","", IFERROR(INDEX(Barang!$C$2:$C$10001, MATCH(C32, Barang!$B$2:$B$10001, 0)), ""))} -> Makanan | E32: {=IF(C32="","", IFERROR(INDEX(Barang!$E$2:$E$10001, MATCH(C32, Barang!$B$2:$B$10001, 0)), ""))} -> pcs | F32: 1 | G32: {=IF(C32="","", IFERROR(INDEX(Barang!$F$2:$F$10001, MATCH(C32, Barang!$B$2:$B$10001, 0)) * F32, ""))} -> 2000 | K32: {=IF(L32="","", IFERROR(INDEX(Barang!$A$2:$A$10001, MATCH(L32, Barang!$B$2:$B$10001, 0)), "Tidak ditemukan"))} | M32: {=IF(L32="","", IFERROR(INDEX(Barang!$C$2:$C$10001, MATCH(L32, Barang!$B$2:$B$10001, 0)), ""))} | N32: {=IF(L32="","", IFERROR(INDEX(Barang!$E$2:$E$10001, MATCH(L32, Barang!$B$2:$B$10001, 0)), ""))} | P32: {=IF(L32="","", IFERROR(INDEX(Barang!$F$2:$F$10001, MATCH(L32, Barang!$B$2:$B$10001, 0)) * O32, ""))} | R32: =#REF!-#REF!+O32 -> #REF! | S32: - | T32: -
A33: 46025 | B33: {=IF(C33="","", IFERROR(INDEX(Barang!$A$2:$A$10001, MATCH(C33, Barang!$B$2:$B$10001, 0)), "Tidak ditemukan"))} -> TLR2 | C33: Telur 1/2 | D33: {=IF(C33="","", IFERROR(INDEX(Barang!$C$2:$C$10001, MATCH(C33, Barang!$B$2:$B$10001, 0)), ""))} -> Sembako | E33: {=IF(C33="","", IFERROR(INDEX(Barang!$E$2:$E$10001, MATCH(C33, Barang!$B$2:$B$10001, 0)), ""))} -> kg | F33: 20 | G33: {=IF(C33="","", IFERROR(INDEX(Barang!$F$2:$F$10001, MATCH(C33, Barang!$B$2:$B$10001, 0)) * F33, ""))} -> 310000 | K33: {=IF(L33="","", IFERROR(INDEX(Barang!$A$2:$A$10001, MATCH(L33, Barang!$B$2:$B$10001, 0)), "Tidak ditemukan"))} | M33: {=IF(L33="","", IFERROR(INDEX(Barang!$C$2:$C$10001, MATCH(L33, Barang!$B$2:$B$10001, 0)), ""))} | N33: {=IF(L33="","", IFERROR(INDEX(Barang!$E$2:$E$10001, MATCH(L33, Barang!$B$2:$B$10001, 0)), ""))} | P33: {=IF(L33="","", IFERROR(INDEX(Barang!$F$2:$F$10001, MATCH(L33, Barang!$B$2:$B$10001, 0)) * O33, ""))} | R33: =#REF!-#REF!+O33 -> #REF! | S33: - | T33: -
B34: {=IF(C34="","", IFERROR(INDEX(Barang!$A$2:$A$10001, MATCH(C34, Barang!$B$2:$B$10001, 0)), "Tidak ditemukan"))} -> TPL2 | C34: Tropical 2Lt | D34: {=IF(C34="","", IFERROR(INDEX(Barang!$C$2:$C$10001, MATCH(C34, Barang!$B$2:$B$10001, 0)), ""))} -> Minyak | E34: {=IF(C34="","", IFERROR(INDEX(Barang!$E$2:$E$10001, MATCH(C34, Barang!$B$2:$B$10001, 0)), ""))} -> Liter | F34: 10 | G34: {=IF(C34="","", IFERROR(INDEX(Barang!$F$2:$F$10001, MATCH(C34, Barang!$B$2:$B$10001, 0)) * F34, ""))} -> 400000 | K34: {=IF(L34="","", IFERROR(INDEX(Barang!$A$2:$A$10001, MATCH(L34, Barang!$B$2:$B$10001, 0)), "Tidak ditemukan"))} | M34: {=IF(L34="","", IFERROR(INDEX(Barang!$C$2:$C$10001, MATCH(L34, Barang!$B$2:$B$10001, 0)), ""))} | N34: {=IF(L34="","", IFERROR(INDEX(Barang!$E$2:$E$10001, MATCH(L34, Barang!$B$2:$B$10001, 0)), ""))} | P34: {=IF(L34="","", IFERROR(INDEX(Barang!$F$2:$F$10001, MATCH(L34, Barang!$B$2:$B$10001, 0)) * O34, ""))} | R34: =#REF!-#REF!+O34 -> #REF! | S34: - | T34: -
